Workbook

Sheet Comparación unificada
A1: DIAN vs SIESA — una fila por tercero; use +/- (o botones 1/2) para ver los documentos; filtre "Estado" en la fila 4
B2: TOTAL GENERAL | E2: =SUMIF($D$5:$D$10000,"TOTAL TERCERO",E5:E10000) -> 3.4554926e+08 | F2: =SUMIF($D$5:$D$10000,"TOTAL TERCERO",F5:F10000) -> 283038611 | G2: =E2-F2 -> 62510653
A4: NIT | B4: Tercero | C4: Documento | D4: Tipo de documento | E4: Valor DIAN | F4: Valor SIESA | G4: Diferencia (DIAN − SIESA) | H4: Estado | I4: Fecha emisión
A5: 805012421 | B5: A.F.TROST HANSEN PRODUCTOS DANCALI SENC | C5: 1 documento(s) | D5: TOTAL TERCERO | E5: =SUMIFS(Base!$H:$H,Base!$A:$A,$A5) -> 0 | F5: =SUMIFS(Base!$I:$I,Base!$A:$A,$A5) -> 100600 | G5: =E5-F5 -> -100600 | H5: Tercero solo en SIESA
A6: 805012421 | B6: A.F.TROST HANSEN PRODUCTOS DANCALI SENC | C6: F20110389 | D6: Factura (solo SIESA) | F6: 100600 | G6: =N(E6)-N(F6) -> -100600 | H6: Solo en SIESA | I6: 46318
A7: 805010086 | B7: ADOCCIDENTE S.A.S. | C7: 1 documento(s) | D7: TOTAL TERCERO | E7: =SUMIFS(Base!$H:$H,Base!$A:$A,$A7) -> 14515620 | F7: =SUMIFS(Base!$I:$I,Base!$A:$A,$A7) -> 14515620 | G7: =E7-F7 -> 0 | H7: Coincide
A8: 805010086 | B8: ADOCCIDENTE S.A.S. | C8: FE1062 | D8: Factura electrónica | E8: 14515620 | F8: 14515620 | G8: =N(E8)-N(F8) -> 0 | H8: Coincide | I8: 46296
A9: 890704196 | B9: AEROVIAS DE INTEGRACION REGIONAL S.A. | C9: 2 documento(s) | D9: TOTAL TERCERO | E9: =SUMIFS(Base!$H:$H,Base!$A:$A,$A9) -> 4972558 | F9: =SUMIFS(Base!$I:$I,Base!$A:$A,$A9) -> 4450876 | G9: =E9-F9 -> 521682 | H9: Con diferencias
A10: 890704196 | B10: AEROVIAS DE INTEGRACION REGIONAL S.A. | C10: EFCC4976394 | D10: Documento equivalente - Transporte aéreo de pasajeros | E10: 521682 | G10: =N(E10)-N(F10) -> 521682 | H10: Solo en DIAN | I10: 46296
A11: 890704196 | B11: AEROVIAS DE INTEGRACION REGIONAL S.A. | C11: SPC45772 | D11: Factura electrónica | E11: 4450876 | F11: 4450876 | G11: =N(E11)-N(F11) -> 0 | H11: Coincide | I11: 46310
A12: 860023024 | B12: AGRICOLA AUTOMOTRIZ S.A.S. | C12: 1 documento(s) | D12: TOTAL TERCERO | E12: =SUMIFS(Base!$H:$H,Base!$A:$A,$A12) -> 2399877.8 | F12: =SUMIFS(Base!$I:$I,Base!$A:$A,$A12) -> 2399877.8 | G12: =E12-F12 -> 0 | H12: Coincide
A13: 860023024 | B13: AGRICOLA AUTOMOTRIZ S.A.S. | C13: 8004129026 | D13: Factura electrónica | E13: 2399877.8 | F13: 2399877.8 | G13: =N(E13)-N(F13) -> 0 | H13: Coincide | I13: 46300
A14: 66807605 | B14: AGUILAR PEREIRA HAYLEM | C14: 1 documento(s) | D14: TOTAL TERCERO | E14: =SUMIFS(Base!$H:$H,Base!$A:$A,$A14) -> 350000 | F14: =SUMIFS(Base!$I:$I,Base!$A:$A,$A14) -> 0 | G14: =E14-F14 -> 350000 | H14: Tercero solo en DIAN
A15: 66807605 | B15: AGUILAR PEREIRA HAYLEM | C15: NDSE1761 | D15: Documento soporte con no obligados | E15: 350000 | G15: =N(E15)-N(F15) -> 350000 | H15: Solo en DIAN | I15: 46317
A16: 16928075 | B16: ALMEIDA BACCA EDWARD ALEXANDER | C16: 3 documento(s) | D16: TOTAL TERCERO | E16: =SUMIFS(Base!$H:$H,Base!$A:$A,$A16) -> 602986.09 | F16: =SUMIFS(Base!$I:$I,Base!$A:$A,$A16) -> 1205969.8 | G16: =E16-F16 -> -602983.71 | H16: Con diferencias
A17: 16928075 | B17: ALMEIDA BACCA EDWARD ALEXANDER | C17: FE689 | D17: Factura electrónica | E17: 598985.31 | F17: 598985.31 | G17: =N(E17)-N(F17) -> 0 | H17: Coincide | I17: 46301
A18: 16928075 | B18: ALMEIDA BACCA EDWARD ALEXANDER | C18: NE31 | D18: Nota de crédito electrónica | E18: -602983.71 | G18: =N(E18)-N(F18) -> -602983.71 | H18: Solo en DIAN | I18: 46301
A19: 16928075 | B19: ALMEIDA BACCA EDWARD ALEXANDER | C19: FE697 | D19: Factura electrónica | E19: 606984.49 | F19: 606984.49 | G19: =N(E19)-N(F19) -> 0 | H19: Coincide | I19: 46303
A20: 900210800 | B20: ANDES SERVICIO DE CERTIFICACION DIGITAL SA | C20: 1 documento(s) | D20: TOTAL TERCERO | E20: =SUMIFS(Base!$H:$H,Base!$A:$A,$A20) -> 130900 | F20: =SUMIFS(Base!$I:$I,Base!$A:$A,$A20) -> 130900 | G20: =E20-F20 -> 0 | H20: Coincide
A21: 900210800 | B21: ANDES SERVICIO DE CERTIFICACION DIGITAL SA | C21: FE178496 | D21: Factura electrónica | E21: 130900 | F21: 130900 | G21: =N(E21)-N(F21) -> 0 | H21: Coincide | I21: 46316
A22: 7563061 | B22: BERRIO ARIAS JUAN FERNANDO | C22: 1 documento(s) | D22: TOTAL TERCERO | E22: =SUMIFS(Base!$H:$H,Base!$A:$A,$A22) -> 300000 | F22: =SUMIFS(Base!$I:$I,Base!$A:$A,$A22) -> 0 | G22: =E22-F22 -> 300000 | H22: Tercero solo en DIAN
A23: 7563061 | B23: BERRIO ARIAS JUAN FERNANDO | C23: NDSE1745 | D23: Documento soporte con no obligados | E23: 300000 | G23: =N(E23)-N(F23) -> 300000 | H23: Solo en DIAN | I23: 46302
A24: 901281572 | B24: BOLD.CO S.A.S | C24: 1 documento(s) | D24: TOTAL TERCERO | E24: =SUMIFS(Base!$H:$H,Base!$A:$A,$A24) -> 210011.46 | F24: =SUMIFS(Base!$I:$I,Base!$A:$A,$A24) -> 0 | G24: =E24-F24 -> 210011.46 | H24: Tercero solo en DIAN
A25: 901281572 | B25: BOLD.CO S.A.S | C25: FEC8813911 | D25: Factura electrónica | E25: 210011.46 | G25: =N(E25)-N(F25) -> 210011.46 | H25: Solo en DIAN | I25: 46307
A26: 901084440 | B26: BRAHAM S.A.S. | C26: 1 documento(s) | D26: TOTAL TERCERO | E26: =SUMIFS(Base!$H:$H,Base!$A:$A,$A26) -> 100000 | F26: =SUMIFS(Base!$I:$I,Base!$A:$A,$A26) -> 100000 | G26: =E26-F26 -> 0 | H26: Coincide
A27: 901084440 | B27: BRAHAM S.A.S. | C27: FELV7089 | D27: Factura electrónica | E27: 100000 | F27: 100000 | G27: =N(E27)-N(F27) -> 0 | H27: Coincide | I27: 46316
A28: 1193142852 | B28: BRAYAN DANILO CORDOBA PERAFAN | C28: 1 documento(s) | D28: TOTAL TERCERO | E28: =SUMIFS(Base!$H:$H,Base!$A:$A,$A28) -> 25000 | F28: =SUMIFS(Base!$I:$I,Base!$A:$A,$A28) -> 0 | G28: =E28-F28 -> 25000 | H28: Tercero solo en DIAN
A29: 1193142852 | B29: BRAYAN DANILO CORDOBA PERAFAN | C29: DJ1763 | D29: Factura electrónica | E29: 25000 | G29: =N(E29)-N(F29) -> 25000 | H29: Solo en DIAN | I29: 46314
A30: 1113519268 | B30: BUENO ALVAREZ WILLIAM ANDRES | C30: 2 documento(s) | D30: TOTAL TERCERO | E30: =SUMIFS(Base!$H:$H,Base!$A:$A,$A30) -> 2628000 | F30: =SUMIFS(Base!$I:$I,Base!$A:$A,$A30) -> 0 | G30: =E30-F30 -> 2628000 | H30: Tercero solo en DIAN
A31: 1113519268 | B31: BUENO ALVAREZ WILLIAM ANDRES | C31: NDSE1750 | D31: Documento soporte con no obligados | E31: 1428000 | G31: =N(E31)-N(F31) -> 1428000 | H31: Solo en DIAN | I31: 46314
A32: 1113519268 | B32: BUENO ALVAREZ WILLIAM ANDRES | C32: NDSE1751 | D32: Documento soporte con no obligados | E32: 1200000 | G32: =N(E32)-N(F32) -> 1200000 | H32: Solo en DIAN | I32: 46314
A33: 901219735 | B33: CAMINOS CREATIVOS MARKETING Y PUBLICIDAD SAS | C33: 1 documento(s) | D33: TOTAL TERCERO | E33: =SUMIFS(Base!$H:$H,Base!$A:$A,$A33) -> 4462500 | F33: =SUMIFS(Base!$I:$I,Base!$A:$A,$A33) -> 4462500 | G33: =E33-F33 -> 0 | H33: Coincide
A34: 901219735 | B34: CAMINOS CREATIVOS MARKETING Y PUBLICIDAD SAS | C34: FE2574 | D34: Factura electrónica | E34: 4462500 | F34: 4462500 | G34: =N(E34)-N(F34) -> 0 | H34: Coincide | I34: 46301
A35: 890321151 | B35: CARVAJAL TECNOLOGIA Y SERVICIOS S.A.S. | C35: 1 documento(s) | D35: TOTAL TERCERO | E35: =SUMIFS(Base!$H:$H,Base!$A:$A,$A35) -> 136776.22 | F35: =SUMIFS(Base!$I:$I,Base!$A:$A,$A35) -> 136776.22 | G35: =E35-F35 -> 0 | H35: Coincide
A36: 890321151 | B36: CARVAJAL TECNOLOGIA Y SERVICIOS S.A.S. | C36: CLOA105299392 | D36: Factura electrónica | E36: 136776.22 | F36: 136776.22 | G36: =N(E36)-N(F36) -> 0 | H36: Coincide | I36: 46300
A37: 67008730 | B37: CHACON MANZANO MARIA DEL CARMEN | C37: 1 documento(s) | D37: TOTAL TERCERO | E37: =SUMIFS(Base!$H:$H,Base!$A:$A,$A37) -> 168000 | F37: =SUMIFS(Base!$I:$I,Base!$A:$A,$A37) -> 168000 | G37: =E37-F37 -> 0 | H37: Coincide
A38: 67008730 | B38: CHACON MANZANO MARIA DEL CARMEN | C38: FEV3320 | D38: Factura electrónica | E38: 168000 | F38: 168000 | G38: =N(E38)-N(F38) -> 0 | H38: Coincide | I38: 46301
A39: 1130588761 | B39: CHRISTIAN CAMILO QUEVEDO OCHOA | C39: 1 documento(s) | D39: TOTAL TERCERO | E39: =SUMIFS(Base!$H:$H,Base!$A:$A,$A39) -> 19000 | F39: =SUMIFS(Base!$I:$I,Base!$A:$A,$A39) -> 19000 | G39: =E39-F39 -> 0 | H39: Coincide
A40: 1130588761 | B40: CHRISTIAN CAMILO QUEVEDO OCHOA | C40: ETPC420 | D40: Factura electrónica | E40: 19000 | F40: 19000 | G40: =N(E40)-N(F40) -> 0 | H40: Coincide | I40: 46298
A41: 890300521 | B41: CLUB COLOMBIA | C41: 3 documento(s) | D41: TOTAL TERCERO | E41: =SUMIFS(Base!$H:$H,Base!$A:$A,$A41) -> 1053750 | F41: =SUMIFS(Base!$I:$I,Base!$A:$A,$A41) -> 1263750 | G41: =E41-F41 -> -210000 | H41: Con diferencias
...

Sheet Base
A1: NIT | B1: Tercero | C1: Documento | D1: Tipo de documento | E1: Grupo DIAN | F1: Fecha emisión | G1: Estado documento | H1: Valor DIAN | I1: Valor SIESA | J1: Diferencia | K1: Estado tercero
A2: 805012421 | B2: A.F.TROST HANSEN PRODUCTOS DANCALI SENC | C2: F20110389 | D2: Factura (solo SIESA) | E2: No está en DIAN | F2: 46318 | G2: Solo en SIESA | I2: 100600 | J2: =N(H2)-N(I2) -> -100600 | K2: Tercero solo en SIESA
A3: 805010086 | B3: ADOCCIDENTE S.A.S. | C3: FE1062 | D3: Factura electrónica | E3: Recibido | F3: 46296 | G3: Coincide | H3: 14515620 | I3: 14515620 | J3: =N(H3)-N(I3) -> 0 | K3: Coincide
A4: 890704196 | B4: AEROVIAS DE INTEGRACION REGIONAL S.A. | C4: EFCC4976394 | D4: Documento equivalente - Transporte aéreo de pasajeros | E4: Recibido | F4: 46296 | G4: Solo en DIAN | H4: 521682 | J4: =N(H4)-N(I4) -> 521682 | K4: Con diferencias
A5: 890704196 | B5: AEROVIAS DE INTEGRACION REGIONAL S.A. | C5: SPC45772 | D5: Factura electrónica | E5: Recibido | F5: 46310 | G5: Coincide | H5: 4450876 | I5: 4450876 | J5: =N(H5)-N(I5) -> 0 | K5: Con diferencias
A6: 860023024 | B6: AGRICOLA AUTOMOTRIZ S.A.S. | C6: 8004129026 | D6: Factura electrónica | E6: Recibido | F6: 46300 | G6: Coincide | H6: 2399877.8 | I6: 2399877.8 | J6: =N(H6)-N(I6) -> 0 | K6: Coincide
A7: 66807605 | B7: AGUILAR PEREIRA HAYLEM | C7: NDSE1761 | D7: Documento soporte con no obligados | E7: Emitido | F7: 46317 | G7: Solo en DIAN | H7: 350000 | J7: =N(H7)-N(I7) -> 350000 | K7: Tercero solo en DIAN
A8: 16928075 | B8: ALMEIDA BACCA EDWARD ALEXANDER | C8: FE689 | D8: Factura electrónica | E8: Recibido | F8: 46301 | G8: Coincide | H8: 598985.31 | I8: 598985.31 | J8: =N(H8)-N(I8) -> 0 | K8: Con diferencias
A9: 16928075 | B9: ALMEIDA BACCA EDWARD ALEXANDER | C9: NE31 | D9: Nota de crédito electrónica | E9: Recibido | F9: 46301 | G9: Solo en DIAN | H9: -602983.71 | J9: =N(H9)-N(I9) -> -602983.71 | K9: Con diferencias
A10: 16928075 | B10: ALMEIDA BACCA EDWARD ALEXANDER | C10: FE697 | D10: Factura electrónica | E10: Recibido | F10: 46303 | G10: Coincide | H10: 606984.49 | I10: 606984.49 | J10: =N(H10)-N(I10) -> 0 | K10: Con diferencias
A11: 900210800 | B11: ANDES SERVICIO DE CERTIFICACION DIGITAL SA | C11: FE178496 | D11: Factura electrónica | E11: Recibido | F11: 46316 | G11: Coincide | H11: 130900 | I11: 130900 | J11: =N(H11)-N(I11) -> 0 | K11: Coincide
A12: 7563061 | B12: BERRIO ARIAS JUAN FERNANDO | C12: NDSE1745 | D12: Documento soporte con no obligados | E12: Emitido | F12: 46302 | G12: Solo en DIAN | H12: 300000 | J12: =N(H12)-N(I12) -> 300000 | K12: Tercero solo en DIAN
A13: 901281572 | B13: BOLD.CO S.A.S | C13: FEC8813911 | D13: Factura electrónica | E13: Recibido | F13: 46307 | G13: Solo en DIAN | H13: 210011.46 | J13: =N(H13)-N(I13) -> 210011.46 | K13: Tercero solo en DIAN
A14: 901084440 | B14: BRAHAM S.A.S. | C14: FELV7089 | D14: Factura electrónica | E14: Recibido | F14: 46316 | G14: Coincide | H14: 100000 | I14: 100000 | J14: =N(H14)-N(I14) -> 0 | K14: Coincide
A15: 1193142852 | B15: BRAYAN DANILO CORDOBA PERAFAN | C15: DJ1763 | D15: Factura electrónica | E15: Recibido | F15: 46314 | G15: Solo en DIAN | H15: 25000 | J15: =N(H15)-N(I15) -> 25000 | K15: Tercero solo en DIAN
A16: 1113519268 | B16: BUENO ALVAREZ WILLIAM ANDRES | C16: NDSE1750 | D16: Documento soporte con no obligados | E16: Emitido | F16: 46314 | G16: Solo en DIAN | H16: 1428000 | J16: =N(H16)-N(I16) -> 1428000 | K16: Tercero solo en DIAN
A17: 1113519268 | B17: BUENO ALVAREZ WILLIAM ANDRES | C17: NDSE1751 | D17: Documento soporte con no obligados | E17: Emitido | F17: 46314 | G17: Solo en DIAN | H17: 1200000 | J17: =N(H17)-N(I17) -> 1200000 | K17: Tercero solo en DIAN
A18: 901219735 | B18: CAMINOS CREATIVOS MARKETING Y PUBLICIDAD SAS | C18: FE2574 | D18: Factura electrónica | E18: Recibido | F18: 46301 | G18: Coincide | H18: 4462500 | I18: 4462500 | J18: =N(H18)-N(I18) -> 0 | K18: Coincide
A19: 890321151 | B19: CARVAJAL TECNOLOGIA Y SERVICIOS S.A.S. | C19: CLOA105299392 | D19: Factura electrónica | E19: Recibido | F19: 46300 | G19: Coincide | H19: 136776.22 | I19: 136776.22 | J19: =N(H19)-N(I19) -> 0 | K19: Coincide
A20: 67008730 | B20: CHACON MANZANO MARIA DEL CARMEN | C20: FEV3320 | D20: Factura electrónica | E20: Recibido | F20: 46301 | G20: Coincide | H20: 168000 | I20: 168000 | J20: =N(H20)-N(I20) -> 0 | K20: Coincide
A21: 1130588761 | B21: CHRISTIAN CAMILO QUEVEDO OCHOA | C21: ETPC420 | D21: Factura electrónica | E21: Recibido | F21: 46298 | G21: Coincide | H21: 19000 | I21: 19000 | J21: =N(H21)-N(I21) -> 0 | K21: Coincide
A22: 890300521 | B22: CLUB COLOMBIA | C22: FS561875 | D22: Factura electrónica | E22: Recibido | F22: 46297 | G22: Coincide | H22: 310000 | I22: 310000 | J22: =N(H22)-N(I22) -> 0 | K22: Con diferencias
A23: 890300521 | B23: CLUB COLOMBIA | C23: FS562580 | D23: Factura electrónica | E23: Recibido | F23: 46303 | G23: Coincide | H23: 743750 | I23: 743750 | J23: =N(H23)-N(I23) -> 0 | K23: Con diferencias
A24: 890300521 | B24: CLUB COLOMBIA | C24: RF129741 | D24: Factura (solo SIESA) | E24: No está en DIAN | F24: 46318 | G24: Solo en SIESA | I24: 210000 | J24: =N(H24)-N(I24) -> -210000 | K24: Con diferencias
A25: 890300225 | B25: COEXITO S.A.S. | C25: 129M77 | D25: Factura electrónica | E25: Recibido | F25: 46296 | G25: Coincide | H25: 15000 | I25: 15000 | J25: =N(H25)-N(I25) -> 0 | K25: Coincide
A26: 901528731 | B26: COLMENA SEGUROS DE VIDA S.A. | C26: VT26386988 | D26: Factura electrónica | E26: Recibido | F26: 46308 | G26: Coincide | H26: 374594.27 | I26: 374594.27 | J26: =N(H26)-N(I26) -> 0 | K26: Coincide
A27: 830122566 | B27: COLOMBIA TELECOMUNICACIONES S.A. E.S.P. BIC | C27: BEC552441113 | D27: Factura electrónica | E27: Recibido | F27: 46306 | G27: Coincide | H27: 21995 | I27: 21995 | J27: =N(H27)-N(I27) -> 0 | K27: Coincide
A28: 830122566 | B28: COLOMBIA TELECOMUNICACIONES S.A. E.S.P. BIC | C28: BEC552442170 | D28: Factura electrónica | E28: Recibido | F28: 46306 | G28: Coincide | H28: 53293 | I28: 53293 | J28: =N(H28)-N(I28) -> 0 | K28: Coincide
A29: 830122566 | B29: COLOMBIA TELECOMUNICACIONES S.A. E.S.P. BIC | C29: BEC552442171 | D29: Factura electrónica | E29: Recibido | F29: 46306 | G29: Coincide | H29: 44875 | I29: 44875 | J29: =N(H29)-N(I29) -> 0 | K29: Coincide
A30: 830122566 | B30: COLOMBIA TELECOMUNICACIONES S.A. E.S.P. BIC | C30: BEC552443055 | D30: Factura electrónica | E30: Recibido | F30: 46306 | G30: Coincide | H30: 12000 | I30: 12000 | J30: =N(H30)-N(I30) -> 0 | K30: Coincide
A31: 830122566 | B31: COLOMBIA TELECOMUNICACIONES S.A. E.S.P. BIC | C31: BEC552443143 | D31: Factura electrónica | E31: Recibido | F31: 46306 | G31: Coincide | H31: 21995 | I31: 21995 | J31: =N(H31)-N(I31) -> 0 | K31: Coincide
A32: 830122566 | B32: COLOMBIA TELECOMUNICACIONES S.A. E.S.P. BIC | C32: BEC552443144 | D32: Factura electrónica | E32: Recibido | F32: 46306 | G32: Coincide | H32: 66348 | I32: 66348 | J32: =N(H32)-N(I32) -> 0 | K32: Coincide
A33: 830122566 | B33: COLOMBIA TELECOMUNICACIONES S.A. E.S.P. BIC | C33: BEC552443145 | D33: Factura electrónica | E33: Recibido | F33: 46306 | G33: Coincide | H33: 21995 | I33: 21995 | J33: =N(H33)-N(I33) -> 0 | K33: Coincide
A34: 830122566 | B34: COLOMBIA TELECOMUNICACIONES S.A. E.S.P. BIC | C34: BEC552443146 | D34: Factura electrónica | E34: Recibido | F34: 46306 | G34: Coincide | H34: 66348 | I34: 66348 | J34: =N(H34)-N(I34) -> 0 | K34: Coincide
A35: 830122566 | B35: COLOMBIA TELECOMUNICACIONES S.A. E.S.P. BIC | C35: BEC552443147 | D35: Factura electrónica | E35: Recibido | F35: 46306 | G35: Coincide | H35: 21995 | I35: 21995 | J35: =N(H35)-N(I35) -> 0 | K35: Coincide
A36: 830122566 | B36: COLOMBIA TELECOMUNICACIONES S.A. E.S.P. BIC | C36: BEC552443148 | D36: Factura electrónica | E36: Recibido | F36: 46306 | G36: Coincide | H36: 44875 | I36: 44875 | J36: =N(H36)-N(I36) -> 0 | K36: Coincide
... A47: 800153993 | B47: COMUNICACION CELULAR S A COMCEL S A | C47: 3292766260 | D47: Factura electrónica | E47: Recibido | F47: 46296 | G47: Coincide | H47: 408700 | I47: 408700 | J47: =N(H47)-N(I47) -> 0 | K47: Coincide
A48: 891500277 | B48: COOPERATIVA INTEGRAL DE TAXIS BELALCAZAR | C48: FTCA352764 | D48: Documento equivalente - Transporte pasajeros terrestre | E48: Recibido | F48: 46314 | G48: Solo en DIAN | H48: 33000 | J48: =N(H48)-N(I48) -> 33000 | K48: Tercero solo en DIAN
A49: 891500277 | B49: COOPERATIVA INTEGRAL DE TAXIS BELALCAZAR | C49: FTPO639435 | D49: Documento equivalente - Transporte pasajeros terrestre | E49: Recibido | F49: 46316 | G49: Solo en DIAN | H49: 33000 | J49: =N(H49)-N(I49) -> 33000 | K49: Tercero solo en DIAN
A50: 890904713 | B50: COORDINADORA MERCANTIL S.A. | C50: D03194002002 | D50: Factura electrónica | E50: Recibido | F50: 46316 | G50: Coincide | H50: 89720 | I50: 89720 | J50: =N(H50)-N(I50) -> 0 | K50: Coincide
...
