Workbook

Sheet Resumen
A1: Resumen de la conciliación DIAN vs Journal — septiembre 2026
A3: Documentos revisados (DIAN + Journal sin DIAN) | B3: =COUNTA(Conciliación!$M$2:$M$486) -> 485
A4: de los cuales presentes en la DIAN | B4: =COUNTIF(Conciliación!$N$2:$N$486,"DIAN") -> 373
A5: de los cuales solo en el Journal | B5: =COUNTIF(Conciliación!$N$2:$N$486,"Journal") -> 112
A6: VERIFICADOS | B6: =COUNTIF(Conciliación!$M$2:$M$486,"VERIFICADO") -> 33
A7: PENDIENTES | B7: =COUNTIF(Conciliación!$M$2:$M$486,"PENDIENTE") -> 239
A8: INFORMACIÓN INSUFICIENTE | B8: =COUNTIF(Conciliación!$M$2:$M$486,"INFORMACIÓN INSUFICIENTE") -> 213
A9: Documentos con diferencia de valor (DIAN vs Journal) | B9: =COUNTIF(Conciliación!$G$2:$G$486,">0")+COUNTIF(Conciliación!$G$2:$G$486,"<0") -> 46
A10: Valor acumulado de diferencias (absoluto) | B10: =SUMIF(Conciliación!$G$2:$G$486,">0")-SUMIF(Conciliación!$G$2:$G$486,"<0") -> 10945453
A11: Valor neto de diferencias (DIAN − Journal) | B11: =SUM(Conciliación!$G$2:$G$486) -> 21837.349
A12: Pendientes + insuficientes enviados a revisión manual | B12: =COUNTA('Pendientes de revisión manual'!$M$2:$M$453) -> 452
A14: Notas de método y límites
A15: 1. Se usaron únicamente los dos archivos (DIAN y Journal); los originales no se modificaron.
A16: 2. Documento DIAN = Prefijo+Folio; el tercero es el Emisor (recibidos) o el Receptor (documentos soporte emitidos). Se cruza por NIT del tercero y folio citado en la referencia/descripción de las líneas del Journal.
A17: 3. Valor en el Journal = suma de las líneas del comprobante de causación del tercero (IVA + otros impuestos + gastos + inventarios/activos + otros). Verificación cruzada: lado proveedor (2205/2210/2335) + retenciones (2365/2367/2368) debe ser igual a esa suma.
A18: 4. ESTADO "Contabilizado": el Journal es un auxiliar contable exportado y NO trae columna de estado. Se asumió que un movimiento en el auxiliar está contabilizado; si existe otro criterio de estado, validar.
A19: 5. LÍMITE DEL ARCHIVO: el Journal tiene 16,383 filas y termina en la cuenta 51251001 (clase 5 incompleta; faltan cuentas de gasto posteriores, clases 6 y 7). Por eso muchas facturas no tienen completas sus líneas de gasto: si el lado proveedor + retenciones coincide con la DIAN quedan como INFORMACIÓN INSUFICIENTE, no VERIFICADO. Volver a exportar el Journal completo (o por rangos de cuenta) y ejecutar de nuevo conciliar.py.
A20: 6. Los registros "solo en el Journal" se limitan a comprobantes que abonan (causan) proveedores/acreedores (2205, 2210, 2335); no se listan pagos, legalizaciones ni notas que solo reducen la cuenta por pagar, ni pagos directos de banco/caja sin causación.
A21: 7. Las diferencias son exactas (sin tolerancia); no se ajustó ningún valor.

Sheet Conciliación
A1: Nombre del tercero | B1: NIT o identificación | C1: Número del documento | D1: Cuenta contable y auxiliar | E1: Valor total según la DIAN | F1: Valor total sumado en el Journal | G1: Diferencia (DIAN − Journal) | H1: Desglose de conceptos contables | I1: Estado en la DIAN | J1: Estado en el Journal | K1: Motivo por el cual queda pendiente | L1: Observaciones para revisión manual | M1: Clasificación | N1: Origen | O1: Comprobante(s) Journal | P1: Fila(s) en el Journal | Q1: Método de cruce | R1: Lado gasto/IVA completo en el Journal
A2: ACEVEDO JOSE NORBEY | B2: 6137792 | C2: NDSE1703 | D2: 23359501 OTROS; 23652507 SERVICIOS GENERALES (DECLARANTES) 4%; 23680203 DEMAS ACTIVIDADES SERVICIOS 10 X 1000 | E2: 289000 | F2: 289000 | G2: =IF(AND(ISNUMBER(E2),ISNUMBER(F2)),E2-F2,"No disponible") -> 0 | H2: Retenciones (crédito): 14,450.00 | Gasto/otros: No disponible (líneas fuera del archivo exportado) | I2: Aprobado con notificación (Documento soporte con no obligados, Emitido) | J2: Presente en el auxiliar (el archivo no trae columna de estado; se infiere Contabilizado) | K2: El lado proveedor + retenciones coincide exacto con la DIAN, pero las líneas de gasto/IVA no están completas en el Journal exportado (el archivo se corta en la fila 16.383); no se puede confirmar la suma de conceptos. | L2: — | M2: INFORMACIÓN INSUFICIENTE | N2: DIAN | O2: 001-DSE-00001703 | P2: 7510, 8236, 9198 | Q2: número del comprobante | R2: No (gasto/IVA cortado en la exportación)
A3: ADOCCIDENTE S.A.S. | B3: 805010086 | C3: FE1043 | D3: 23359501 OTROS; 23652507 SERVICIOS GENERALES (DECLARANTES) 4%; 23653002 BIENES INMUEBLES 3,5%; 24081513 IVA TRANSITORIO SERVICIOS 19% | E3: 17074120 | F3: 17074120 | G3: =IF(AND(ISNUMBER(E3),ISNUMBER(F3)),E3-F3,"No disponible") -> 0 | H3: IVA: 2,726,120.00 | Retenciones (crédito): 523,680.00 | Gasto/otros: No disponible (líneas fuera del archivo exportado) | I3: Aprobado con notificación (Factura electrónica, Recibido) | J3: Presente en el auxiliar (el archivo no trae columna de estado; se infiere Contabilizado) | K3: El lado proveedor + retenciones coincide exacto con la DIAN, pero las líneas de gasto/IVA no están completas en el Journal exportado (el archivo se corta en la fila 16.383); no se puede confirmar la suma de conceptos. | L3: — | M3: INFORMACIÓN INSUFICIENTE | N3: DIAN | O3: 001-FSC-00011343 | P3: 7642, 8252, 8326, 11263 | Q3: referencia | R3: No (gasto/IVA cortado en la exportación)
A4: AEROVIAS DE INTEGRACION REGIONAL S.A. | B4: 890704196 | C4: A3933 | D4: 23354501 TRANSPORTES, FLETES Y ACARREOS | E4: 939272 | F4: 939272 | G4: =IF(AND(ISNUMBER(E4),ISNUMBER(F4)),E4-F4,"No disponible") -> 0 | H4: Retenciones (crédito): 0.00 | Gasto/otros: No disponible (líneas fuera del archivo exportado) | I4: Aprobado con notificación (Nota de crédito electrónica, Recibido) | J4: Presente en el auxiliar (el archivo no trae columna de estado; se infiere Contabilizado) | K4: El lado proveedor + retenciones coincide exacto con la DIAN, pero las líneas de gasto/IVA no están completas en el Journal exportado (el archivo se corta en la fila 16.383); no se puede confirmar la suma de conceptos. | L4: La descripción del comprobante menciona ANULACIÓN: confirmar que no esté anulado. | M4: INFORMACIÓN INSUFICIENTE | N4: DIAN | O4: 001-NT-00012697 | P4: 7357 | Q4: texto/descripción | R4: No (gasto/IVA cortado en la exportación)
A5: AEROVIAS DE INTEGRACION REGIONAL S.A. | B5: 890704196 | C5: SPC44755 | D5: 23354501 TRANSPORTES, FLETES Y ACARREOS | E5: 13701380 | F5: 13701380 | G5: =IF(AND(ISNUMBER(E5),ISNUMBER(F5)),E5-F5,"No disponible") -> 0 | H5: Retenciones (crédito): 0.00 | Gasto/otros: No disponible (líneas fuera del archivo exportado) | I5: Aprobado con notificación (Factura electrónica, Recibido) | J5: Presente en el auxiliar (el archivo no trae columna de estado; se infiere Contabilizado) | K5: El lado proveedor + retenciones coincide exacto con la DIAN, pero las líneas de gasto/IVA no están completas en el Journal exportado (el archivo se corta en la fila 16.383); no se puede confirmar la suma de conceptos. | L5: — | M5: INFORMACIÓN INSUFICIENTE | N5: DIAN | O5: 001-FSC-00011436 | P5: 7353 | Q5: referencia | R5: No (gasto/IVA cortado en la exportación)
A6: AEROVIAS DE INTEGRACION REGIONAL S.A. | B6: 890704196 | C6: SPC45219 | D6: 23354501 TRANSPORTES, FLETES Y ACARREOS | E6: 4535050 | F6: 4535050 | G6: =IF(AND(ISNUMBER(E6),ISNUMBER(F6)),E6-F6,"No disponible") -> 0 | H6: Retenciones (crédito): 0.00 | Gasto/otros: No disponible (líneas fuera del archivo exportado) | I6: Aprobado con notificación (Factura electrónica, Recibido) | J6: Presente en el auxiliar (el archivo no trae columna de estado; se infiere Contabilizado) | K6: El lado proveedor + retenciones coincide exacto con la DIAN, pero las líneas de gasto/IVA no están completas en el Journal exportado (el archivo se corta en la fila 16.383); no se puede confirmar la suma de conceptos. | L6: — | M6: INFORMACIÓN INSUFICIENTE | N6: DIAN | O6: 001-FSC-00011580 | P6: 7356 | Q6: referencia | R6: No (gasto/IVA cortado en la exportación)
A7: AEROVIAS DE INTEGRACIÓN REGIONAL S.A. | B7: 890704196 | C7: EFCC4800912 | D7: 23354501 TRANSPORTES, FLETES Y ACARREOS; 24081513 IVA TRANSITORIO SERVICIOS 19% | E7: 3317339 | F7: 3317399 | G7: =IF(AND(ISNUMBER(E7),ISNUMBER(F7)),E7-F7,"No disponible") -> -60 | H7: IVA: 521,750.00 | Retenciones (crédito): 0.00 | Gasto/otros: No disponible (líneas fuera del archivo exportado) | I7: Aprobado con notificación (Documento equivalente - Transporte aéreo de pasajeros, Recibido) | J7: Presente en el auxiliar (el archivo no trae columna de estado; se infiere Contabilizado) | K7: El lado proveedor + retenciones del Journal no coincide con el total de la DIAN. | L7: — | M7: PENDIENTE | N7: DIAN | O7: 001-FSC-00011488 | P7: 7354, 11339 | Q7: referencia | R7: No (gasto/IVA cortado en la exportación)
A8: AEROVIAS DE INTEGRACIÓN REGIONAL S.A. | B8: 890704196 | C8: EFCC4858340 | D8: No disponible | E8: 417940 | F8: No encontrado | G8: =IF(AND(ISNUMBER(E8),ISNUMBER(F8)),E8-F8,"No disponible") -> No disponible | H8: No disponible | I8: Aprobado con notificación (Documento equivalente - Transporte aéreo de pasajeros, Recibido) | J8: No encontrado | K8: No se encontró el documento en el Journal (el tercero sí tiene otros movimientos). | L8: El tercero aparece en el Journal pero ninguna línea cita este folio ni coincide su valor. | M8: PENDIENTE | N8: DIAN | O8: No encontrado | Q8: No encontrado | R8: No disponible
A9: AEROVIAS DEL CONTINENTE AMERICANO, S.A. AVIANCA - COLOMBIA | B9: 890100577 | C9: TQT26949290 | D9: 23359501 OTROS; 24081513 IVA TRANSITORIO SERVICIOS 19% | E9: 553160 | F9: 553160 | G9: =IF(AND(ISNUMBER(E9),ISNUMBER(F9)),E9-F9,"No disponible") -> 0 | H9: IVA: 84,360.00 | Retenciones (crédito): 0.00 | Gasto/otros: No disponible (líneas fuera del archivo exportado) | I9: Aprobado con notificación (Factura electrónica, Recibido) | J9: Presente en el auxiliar (el archivo no trae columna de estado; se infiere Contabilizado) | K9: El lado proveedor + retenciones coincide exacto con la DIAN, pero las líneas de gasto/IVA no están completas en el Journal exportado (el archivo se corta en la fila 16.383); no se puede confirmar la suma de conceptos. | L9: — | M9: INFORMACIÓN INSUFICIENTE | N9: DIAN | O9: 001-FSC-00011450 | P9: 7747, 11304 | Q9: referencia | R9: No (gasto/IVA cortado en la exportación)
A10: AGENCIA DE ADUANAS SANTIAGO RICO & BAÑOL LTDA. NIVEL 4 | B10: 827000059 | C10: SRFE804 | D10: 23359501 OTROS; 23652507 SERVICIOS GENERALES (DECLARANTES) 4% | E10: 450000 | F10: 450000 | G10: =IF(AND(ISNUMBER(E10),ISNUMBER(F10)),E10-F10,"No disponible") -> 0 | H10: Retenciones (crédito): 18,000.00 | Gasto/otros: No disponible (líneas fuera del archivo exportado) | I10: Aprobado con notificación (Factura electrónica, Recibido) | J10: Presente en el auxiliar (el archivo no trae columna de estado; se infiere Contabilizado) | K10: El lado proveedor + retenciones coincide exacto con la DIAN, pero las líneas de gasto/IVA no están completas en el Journal exportado (el archivo se corta en la fila 16.383); no se puede confirmar la suma de conceptos. | L10: — | M10: INFORMACIÓN INSUFICIENTE | N10: DIAN | O10: 001-FSC-00011385 | P10: 7680, 8256 | Q10: referencia | R10: No (gasto/IVA cortado en la exportación)
A11: AGENCIA DE ADUANAS SANTIAGO RICO & BAÑOL LTDA. NIVEL 4 | B11: 827000059 | C11: SRFE813 | D11: 23359501 OTROS; 23652507 SERVICIOS GENERALES (DECLARANTES) 4%; 26952001 PARA OPERACION | E11: 3150000 | F11: 3150000 | G11: =IF(AND(ISNUMBER(E11),ISNUMBER(F11)),E11-F11,"No disponible") -> 0 | H11: Otros conceptos: 3,150,000.00 | Retenciones (crédito): 126,000.00 | I11: Aprobado con notificación (Factura electrónica, Recibido) | J11: Presente en el auxiliar (el archivo no trae columna de estado; se infiere Contabilizado) | K11: Coincide exacto (débitos = créditos = DIAN). | L11: — | M11: VERIFICADO | N11: DIAN | O11: 001-CC-00023130 | P11: 7682, 8257, 12537 | Q11: referencia | R11: Sí
A12: AGENCIA DE ADUANAS SANTIAGO RICO & BAÑOL LTDA. NIVEL 4 | B12: 827000059 | C12: SRFE817 | D12: 23359501 OTROS; 23652507 SERVICIOS GENERALES (DECLARANTES) 4%; 26952001 PARA OPERACION | E12: 450000 | F12: 449999 | G12: =IF(AND(ISNUMBER(E12),ISNUMBER(F12)),E12-F12,"No disponible") -> 1 | H12: Otros conceptos: 449,999.00 | Retenciones (crédito): 18,000.00 | I12: Aprobado con notificación (Factura electrónica, Recibido) | J12: Presente en el auxiliar (el archivo no trae columna de estado; se infiere Contabilizado) | K12: La suma de los conceptos contables no coincide con el total de la DIAN. | L12: — | M12: PENDIENTE | N12: DIAN | O12: 001-CC-00023131 | P12: 7683, 8258, 12538 | Q12: referencia | R12: Sí
A13: ALMACEN LAS GEMELAS SAS | B13: 901849101 | C13: FE2169 | D13: 23359501 OTROS; 23654002 COMPRAS GENERALES 2,5%; 24081510 IVA TRANSITORIO COMPRAS 19% | E13: 792000.02 | F13: 792000 | G13: =IF(AND(ISNUMBER(E13),ISNUMBER(F13)),E13-F13,"No disponible") -> 0.02 | H13: IVA: 126,454.00 | Retenciones (crédito): 16,639.00 | Gasto/otros: No disponible (líneas fuera del archivo exportado) | I13: Aprobado con notificación (Factura electrónica, Recibido) | J13: Presente en el auxiliar (el archivo no trae columna de estado; se infiere Contabilizado) | K13: El lado proveedor + retenciones del Journal no coincide con el total de la DIAN. | L13: — | M13: PENDIENTE | N13: DIAN | O13: 001-FSC-00011456 | P13: 8028, 8415, 11207 | Q13: referencia | R13: No (gasto/IVA cortado en la exportación)
A14: ALMACENES ÉXITO S.A | B14: 890900608 | C14: RC06172758 | D14: 23359501 OTROS | E14: 37080 | F14: 37080 | G14: =IF(AND(ISNUMBER(E14),ISNUMBER(F14)),E14-F14,"No disponible") -> 0 | H14: Retenciones (crédito): 0.00 | Gasto/otros: No disponible (líneas fuera del archivo exportado) | I14: Aprobado con notificación (Factura electrónica, Recibido) | J14: Presente en el auxiliar (el archivo no trae columna de estado; se infiere Contabilizado) | K14: El lado proveedor + retenciones coincide exacto con la DIAN, pero las líneas de gasto/IVA no están completas en el Journal exportado (el archivo se corta en la fila 16.383); no se puede confirmar la suma de conceptos. | L14: — | M14: INFORMACIÓN INSUFICIENTE | N14: DIAN | O14: 001-FSC-00011592 | P14: 7822 | Q14: referencia | R14: No (gasto/IVA cortado en la exportación)
A15: ALMAZONE SAS | B15: 901881638 | C15: ALZ2401 | D15: 22050501 PROVEEDORES NACIONALES; 23652501 TRANSPORTE 1%; 26959501 OTRAS | E15: 1850000 | F15: 1850000 | G15: =IF(AND(ISNUMBER(E15),ISNUMBER(F15)),E15-F15,"No disponible") -> 0 | H15: Otros conceptos: 1,850,000.00 | Retenciones (crédito): 18,500.00 | I15: Aprobado con notificación (Factura electrónica, Recibido) | J15: Presente en el auxiliar (el archivo no trae columna de estado; se infiere Contabilizado) | K15: Coincide exacto (débitos = créditos = DIAN). | L15: — | M15: VERIFICADO | N15: DIAN | O15: 001-FPI-00000500 | P15: 7247, 8197, 12632 | Q15: referencia | R15: Sí
A16: ALMEIDA BACCA EDWARD ALEXANDER | B16: 16928075 | C16: FE681 | D16: No disponible | E16: 601985.3 | F16: No encontrado | G16: =IF(AND(ISNUMBER(E16),ISNUMBER(F16)),E16-F16,"No disponible") -> No disponible | H16: No disponible | I16: Aprobado con notificación (Factura electrónica, Recibido) | J16: No encontrado | K16: El tercero no aparece en el Journal. | L16: NIT sin movimientos en el archivo del Journal. | M16: PENDIENTE | N16: DIAN | O16: No encontrado | Q16: No encontrado | R16: No disponible
A17: ANILLANDO CALI LTDA | B17: 800038947 | C17: PFS10547 | D17: 22050501 PROVEEDORES NACIONALES; 24081510 IVA TRANSITORIO COMPRAS 19% | E17: 138900 | F17: 138900 | G17: =IF(AND(ISNUMBER(E17),ISNUMBER(F17)),E17-F17,"No disponible") -> 0 | H17: IVA: 22,177.00 | Retenciones (crédito): 0.00 | Gasto/otros: No disponible (líneas fuera del archivo exportado) | I17: Aprobado con notificación (Factura electrónica, Recibido) | J17: Presente en el auxiliar (el archivo no trae columna de estado; se infiere Contabilizado) | K17: El lado proveedor + retenciones coincide exacto con la DIAN, pero las líneas de gasto/IVA no están completas en el Journal exportado (el archivo se corta en la fila 16.383); no se puede confirmar la suma de conceptos. | L17: — | M17: INFORMACIÓN INSUFICIENTE | N17: DIAN | O17: 001-FSC-00011410 | P17: 7203, 11063 | Q17: referencia | R17: No (gasto/IVA cortado en la exportación)
A18: APONTE CASTILLO CARLOS DANIEL | B18: 1010204688 | C18: 422 | D18: 13309501 OTROS; 23359501 OTROS; 23654002 COMPRAS GENERALES 2,5%; 24081510 IVA TRANSITORIO COMPRAS 19% | E18: 6961500 | F18: 3553875 | G18: =IF(AND(ISNUMBER(E18),ISNUMBER(F18)),E18-F18,"No disponible") -> 3407625 | H18: IVA: 1,111,500.00 | Otros conceptos: -3,407,625.00 | Retenciones (crédito): 146,250.00 | Gasto/otros: No disponible (líneas fuera del archivo exportado) | I18: Aprobado con notificación (Factura electrónica, Recibido) | J18: Presente en el auxiliar (el archivo no trae columna de estado; se infiere Contabilizado) | K18: El lado proveedor + retenciones del Journal no coincide con el total de la DIAN. | L18: — | M18: PENDIENTE | N18: DIAN | O18: 001-FSC-00011398 | P18: 3306, 7373, 7374, 8332, 11047 | Q18: referencia | R18: No (gasto/IVA cortado en la exportación)
A19: AQUASISTEMAS DEL CARIBE S.A.S | B19: 802018827 | C19: FE232 | D19: 23359501 OTROS; 23654002 COMPRAS GENERALES 2,5% | E19: 561300 | F19: 561300 | G19: =IF(AND(ISNUMBER(E19),ISNUMBER(F19)),E19-F19,"No disponible") -> 0 | H19: Retenciones (crédito): 14,033.00 | Gasto/otros: No disponible (líneas fuera del archivo exportado) | I19: Aprobado con notificación (Factura electrónica, Recibido) | J19: Presente en el auxiliar (el archivo no trae columna de estado; se infiere Contabilizado) | K19: El lado proveedor + retenciones coincide exacto con la DIAN, pero las líneas de gasto/IVA no están completas en el Journal exportado (el archivo se corta en la fila 16.383); no se puede confirmar la suma de conceptos. | L19: — | M19: INFORMACIÓN INSUFICIENTE | N19: DIAN | O19: 001-FSC-00011582 | P19: 7637, 8367 | Q19: referencia | R19: No (gasto/IVA cortado en la exportación)
A20: ARIAS GLORIA PATRICIA | B20: 31411095 | C20: NDSE1700 | D20: 23359501 OTROS; 23654002 COMPRAS GENERALES 2,5%; 23680302 DEMAS ACTIVIDADES COMERCIALES 7,7 X 1000 | E20: 1620000 | F20: 1620000 | G20: =IF(AND(ISNUMBER(E20),ISNUMBER(F20)),E20-F20,"No disponible") -> 0 | H20: Retenciones (crédito): 52,974.00 | Gasto/otros: No disponible (líneas fuera del archivo exportado) | I20: Aprobado con notificación (Documento soporte con no obligados, Emitido) | J20: Presente en el auxiliar (el archivo no trae columna de estado; se infiere Contabilizado) | K20: El lado proveedor + retenciones coincide exacto con la DIAN, pero las líneas de gasto/IVA no están completas en el Journal exportado (el archivo se corta en la fila 16.383); no se puede confirmar la suma de conceptos. | L20: — | M20: INFORMACIÓN INSUFICIENTE | N20: DIAN | O20: 001-DSE-00001700 | P20: 7458, 8344, 9261 | Q20: referencia | R20: No (gasto/IVA cortado en la exportación)
A21: ARIAS GLORIA PATRICIA | B21: 31411095 | C21: NDSE1708 | D21: 23359501 OTROS; 23654002 COMPRAS GENERALES 2,5%; 23680203 DEMAS ACTIVIDADES SERVICIOS 10 X 1000 | E21: 3000000 | F21: 3000000 | G21: =IF(AND(ISNUMBER(E21),ISNUMBER(F21)),E21-F21,"No disponible") -> 0 | H21: Retenciones (crédito): 105,000.00 | Gasto/otros: No disponible (líneas fuera del archivo exportado) | I21: Aprobado con notificación (Documento soporte con no obligados, Emitido) | J21: Presente en el auxiliar (el archivo no trae columna de estado; se infiere Contabilizado) | K21: El lado proveedor + retenciones coincide exacto con la DIAN, pero las líneas de gasto/IVA no están completas en el Journal exportado (el archivo se corta en la fila 16.383); no se puede confirmar la suma de conceptos. | L21: — | M21: INFORMACIÓN INSUFICIENTE | N21: DIAN | O21: 001-DSE-00001708 | P21: 7460, 7461, 8345, 9195 | Q21: referencia | R21: No (gasto/IVA cortado en la exportación)
A22: ARIAS GLORIA PATRICIA | B22: 31411095 | C22: NDSE1734 | D22: 23359501 OTROS; 23652507 SERVICIOS GENERALES (DECLARANTES) 4%; 23680203 DEMAS ACTIVIDADES SERVICIOS 10 X 1000; 51055101 DOTACION Y SUMINISTRO A TRABAJADORES | E22: 636500 | F22: 636500 | G22: =IF(AND(ISNUMBER(E22),ISNUMBER(F22)),E22-F22,"No disponible") -> 0 | H22: Gastos: 38,000.00 | Retenciones (crédito): 31,825.00 | Gasto/otros: No disponible (líneas fuera del archivo exportado) | I22: Aprobado con notificación (Documento soporte con no obligados, Emitido) | J22: Presente en el auxiliar (el archivo no trae columna de estado; se infiere Contabilizado) | K22: El lado proveedor + retenciones coincide exacto con la DIAN, pero las líneas de gasto/IVA no están completas en el Journal exportado (el archivo se corta en la fila 16.383); no se puede confirmar la suma de conceptos. | L22: — | M22: INFORMACIÓN INSUFICIENTE | N22: DIAN | O22: 001-DSE-00001734 | P22: 7464, 8234, 9196, 16105 | Q22: referencia | R22: No (gasto/IVA cortado en la exportación)
A23: ASESORIAS REPRESENTACIONES ADMINISTRACION Y SERVICIOS ARAS SAS. | B23: 860506531 | C23: MCBU162585 | D23: 23359501 OTROS; 26959501 OTRAS | E23: 275000 | F23: 275000 | G23: =IF(AND(ISNUMBER(E23),ISNUMBER(F23)),E23-F23,"No disponible") -> 0 | H23: Otros conceptos: 275,000.00 | Retenciones (crédito): 0.00 | I23: Aprobado con notificación (Factura electrónica, Recibido) | J23: Presente en el auxiliar (el archivo no trae columna de estado; se infiere Contabilizado) | K23: Coincide exacto (débitos = créditos = DIAN). | L23: — | M23: VERIFICADO | N23: DIAN | O23: 001-FPI-00000496 | P23: 7740, 12625 | Q23: referencia | R23: Sí
A24: AZUL RESTAURANT AIRPORT | B24: 79308344 | C24: PAZ6314 | D24: 23359501 OTROS | E24: 24000 | F24: 24000 | G24: =IF(AND(ISNUMBER(E24),ISNUMBER(F24)),E24-F24,"No disponible") -> 0 | H24: Retenciones (crédito): 0.00 | Gasto/otros: No disponible (líneas fuera del archivo exportado) | I24: Aprobado con notificación (Factura electrónica, Recibido) | J24: Presente en el auxiliar (el archivo no trae columna de estado; se infiere Contabilizado) | K24: Coincide el NIT y el valor exacto, pero ninguna línea del Journal cita el número del documento; no se puede identificar con certeza. | L24: — | M24: INFORMACIÓN INSUFICIENTE | N24: DIAN | O24: 001-FSC-00011438 | P24: 7540 | Q24: NIT + valor (sin folio) | R24: No (gasto/IVA cortado en la exportación)
A25: AZUL RESTAURANT AIRPORT | B25: 79308344 | C25: PAZ6315 | D25: 23359501 OTROS | E25: 26000 | F25: 26000 | G25: =IF(AND(ISNUMBER(E25),ISNUMBER(F25)),E25-F25,"No disponible") -> 0 | H25: Retenciones (crédito): 0.00 | Gasto/otros: No disponible (líneas fuera del archivo exportado) | I25: Aprobado con notificación (Factura electrónica, Recibido) | J25: Presente en el auxiliar (el archivo no trae columna de estado; se infiere Contabilizado) | K25: El lado proveedor + retenciones coincide exacto con la DIAN, pero las líneas de gasto/IVA no están completas en el Journal exportado (el archivo se corta en la fila 16.383); no se puede confirmar la suma de conceptos. | L25: — | M25: INFORMACIÓN INSUFICIENTE | N25: DIAN | O25: 001-FSC-00011482 | P25: 7545 | Q25: referencia | R25: No (gasto/IVA cortado en la exportación)
A26: AZUL RESTAURANT AIRPORT | B26: 79308344 | C26: PAZ6316 | D26: No disponible | E26: 10000 | F26: No encontrado | G26: =IF(AND(ISNUMBER(E26),ISNUMBER(F26)),E26-F26,"No disponible") -> No disponible | H26: No disponible | I26: Aprobado con notificación (Factura electrónica, Recibido) | J26: No encontrado | K26: No se encontró el documento en el Journal (el tercero sí tiene otros movimientos). | L26: El tercero aparece en el Journal pero ninguna línea cita este folio ni coincide su valor. | M26: PENDIENTE | N26: DIAN | O26: No encontrado | Q26: No encontrado | R26: No disponible
A27: BAL STUDIO SAS | B27: 901986829 | C27: FE2458 | D27: 22050501 PROVEEDORES NACIONALES; 23670501 IVA RET. COMPRAS RC 15%; 24081513 IVA TRANSITORIO SERVICIOS 19% | E27: 2023000 | F27: 2023000 | G27: =IF(AND(ISNUMBER(E27),ISNUMBER(F27)),E27-F27,"No disponible") -> 0 | H27: IVA: 323,000.00 | Retenciones (crédito): 48,450.00 | Gasto/otros: No disponible (líneas fuera del archivo exportado) | I27: Aprobado con notificación (Factura electrónica, Recibido) | J27: Presente en el auxiliar (el archivo no trae columna de estado; se infiere Contabilizado) | K27: El lado proveedor + retenciones coincide exacto con la DIAN, pero las líneas de gasto/IVA no están completas en el Journal exportado (el archivo se corta en la fila 16.383); no se puede confirmar la suma de conceptos. | L27: — | M27: INFORMACIÓN INSUFICIENTE | N27: DIAN | O27: 001-FSC-00011483 | P27: 7250, 9156, 11501 | Q27: referencia | R27: No (gasto/IVA cortado en la exportación)
A28: BBVA SEGUROS COLOMBIA S.A. | B28: 800226098 | C28: FEAG1134986 | D28: 23359501 OTROS; 24081513 IVA TRANSITORIO SERVICIOS 19% | E28: 178364 | F28: 178364 | G28: =IF(AND(ISNUMBER(E28),ISNUMBER(F28)),E28-F28,"No disponible") -> 0 | H28: IVA: 28,478.00 | Retenciones (crédito): 0.00 | Gasto/otros: No disponible (líneas fuera del archivo exportado) | I28: Aprobado con notificación (Factura electrónica, Recibido) | J28: Presente en el auxiliar (el archivo no trae columna de estado; se infiere Contabilizado) | K28: El lado proveedor + retenciones coincide exacto con la DIAN, pero las líneas de gasto/IVA no están completas en el Journal exportado (el archivo se corta en la fila 16.383); no se puede confirmar la suma de conceptos. | L28: — | M28: INFORMACIÓN INSUFICIENTE | N28: DIAN | O28: 001-FSC-00011380 | P28: 7588, 11253 | Q28: referencia | R28: No (gasto/IVA cortado en la exportación)
A29: BENEMERITO CUERPO DE BOMBEROS VOLUNTARIOS DE CALI | B29: 890399000 | C29: FK72753 | D29: 23359501 OTROS; 24081513 IVA TRANSITORIO SERVICIOS 19% | E29: 942994 | F29: 942994 | G29: =IF(AND(ISNUMBER(E29),ISNUMBER(F29)),E29-F29,"No disponible") -> 0 | H29: IVA: 150,562.00 | Retenciones (crédito): 0.00 | Gasto/otros: No disponible (líneas fuera del archivo exportado) | I29: Aprobado con notificación (Factura electrónica, Recibido) | J29: Presente en el auxiliar (el archivo no trae columna de estado; se infiere Contabilizado) | K29: El lado proveedor + retenciones coincide exacto con la DIAN, pero las líneas de gasto/IVA no están completas en el Journal exportado (el archivo se corta en la fila 16.383); no se puede confirmar la suma de conceptos. | L29: — | M29: INFORMACIÓN INSUFICIENTE | N29: DIAN | O29: 001-FSC-00011563 | P29: 7799, 11332 | Q29: referencia | R29: No (gasto/IVA cortado en la exportación)
A30: BERMUDEZ RAMIREZ EUCARIO | B30: 16752920 | C30: NDSE1709 | D30: 22050501 PROVEEDORES NACIONALES; 23654002 COMPRAS GENERALES 2,5%; 23680302 DEMAS ACTIVIDADES COMERCIALES 7,7 X 1000 | E30: 11480000 | F30: 11480000 | G30: =IF(AND(ISNUMBER(E30),ISNUMBER(F30)),E30-F30,"No disponible") -> 0 | H30: Retenciones (crédito): 375,396.00 | Gasto/otros: No disponible (líneas fuera del archivo exportado) | I30: Aprobado con notificación (Documento soporte con no obligados, Emitido) | J30: Presente en el auxiliar (el archivo no trae columna de estado; se infiere Contabilizado) | K30: El lado proveedor + retenciones coincide exacto con la DIAN, pero las líneas de gasto/IVA no están completas en el Journal exportado (el archivo se corta en la fila 16.383); no se puede confirmar la suma de conceptos. | L30: — | M30: INFORMACIÓN INSUFICIENTE | N30: DIAN | O30: 001-DSE-00001709 | P30: 7195, 8335, 9255 | Q30: referencia | R30: No (gasto/IVA cortado en la exportación)
A31: BERNARDA VALENCIA MOYA | B31: 29951774 | C31: FEBV2769 | D31: 23359502 CUENTA PUENTE CAJA MENOR | E31: 20000 | F31: 20000 | G31: =IF(AND(ISNUMBER(E31),ISNUMBER(F31)),E31-F31,"No disponible") -> 0 | H31: Retenciones (crédito): 0.00 | Gasto/otros: No disponible (líneas fuera del archivo exportado) | I31: Aprobado con notificación (Factura electrónica, Recibido) | J31: Presente en el auxiliar (el archivo no trae columna de estado; se infiere Contabilizado) | K31: El lado proveedor + retenciones coincide exacto con la DIAN, pero las líneas de gasto/IVA no están completas en el Journal exportado (el archivo se corta en la fila 16.383); no se puede confirmar la suma de conceptos. | L31: — | M31: INFORMACIÓN INSUFICIENTE | N31: DIAN | O31: 001-FSC-00011557 | P31: 8084 | Q31: referencia | R31: No (gasto/IVA cortado en la exportación)
A32: BERRIO ARIAS JUAN FERNANDO | B32: 7563061 | C32: NDSE1733 | D32: 23359501 OTROS; 23652507 SERVICIOS GENERALES (DECLARANTES) 4% | E32: 145000 | F32: 145000 | G32: =IF(AND(ISNUMBER(E32),ISNUMBER(F32)),E32-F32,"No disponible") -> 0 | H32: Retenciones (crédito): 5,800.00 | Gasto/otros: No disponible (líneas fuera del archivo exportado) | I32: Aprobado con notificación (Documento soporte con no obligados, Emitido) | J32: Presente en el auxiliar (el archivo no trae columna de estado; se infiere Contabilizado) | K32: El lado proveedor + retenciones coincide exacto con la DIAN, pero las líneas de gasto/IVA no están completas en el Journal exportado (el archivo se corta en la fila 16.383); no se puede confirmar la suma de conceptos. | L32: — | M32: INFORMACIÓN INSUFICIENTE | N32: DIAN | O32: 001-DSE-00001733 | P32: 7538, 8238 | Q32: número del comprobante | R32: No (gasto/IVA cortado en la exportación)
A33: BOLD.CO S.A.S | B33: 901281572 | C33: FEC8613219 | D33: No disponible | E33: 137076.57 | F33: No encontrado | G33: =IF(AND(ISNUMBER(E33),ISNUMBER(F33)),E33-F33,"No disponible") -> No disponible | H33: No disponible | I33: Aprobado con notificación (Factura electrónica, Recibido) | J33: No encontrado | K33: No se encontró el documento en el Journal (el tercero sí tiene otros movimientos). | L33: El tercero aparece en el Journal pero ninguna línea cita este folio ni coincide su valor. | M33: PENDIENTE | N33: DIAN | O33: No encontrado | Q33: No encontrado | R33: No disponible
A34: BUENO ALVAREZ WILLIAM ANDRES | B34: 1113519268 | C34: NDSE1704 | D34: 23359501 OTROS | E34: 1730560 | F34: 1730560 | G34: =IF(AND(ISNUMBER(E34),ISNUMBER(F34)),E34-F34,"No disponible") -> 0 | H34: Retenciones (crédito): 0.00 | Gasto/otros: No disponible (líneas fuera del archivo exportado) | I34: Aprobado con notificación (Documento soporte con no obligados, Emitido) | J34: Presente en el auxiliar (el archivo no trae columna de estado; se infiere Contabilizado) | K34: El lado proveedor + retenciones coincide exacto con la DIAN, pero las líneas de gasto/IVA no están completas en el Journal exportado (el archivo se corta en la fila 16.383); no se puede confirmar la suma de conceptos. | L34: — | M34: INFORMACIÓN INSUFICIENTE | N34: DIAN | O34: 001-DSE-00001704 | P34: 7387 | Q34: referencia | R34: No (gasto/IVA cortado en la exportación)
A35: BUENO ALVAREZ WILLIAM ANDRES | B35: 1113519268 | C35: NDSE1705 | D35: 23359501 OTROS | E35: 1732000 | F35: 1732000 | G35: =IF(AND(ISNUMBER(E35),ISNUMBER(F35)),E35-F35,"No disponible") -> 0 | H35: Retenciones (crédito): 0.00 | Gasto/otros: No disponible (líneas fuera del archivo exportado) | I35: Aprobado con notificación (Documento soporte con no obligados, Emitido) | J35: Presente en el auxiliar (el archivo no trae columna de estado; se infiere Contabilizado) | K35: El lado proveedor + retenciones coincide exacto con la DIAN, pero las líneas de gasto/IVA no están completas en el Journal exportado (el archivo se corta en la fila 16.383); no se puede confirmar la suma de conceptos. | L35: — | M35: INFORMACIÓN INSUFICIENTE | N35: DIAN | O35: 001-DSE-00001705 | P35: 7388 | Q35: referencia | R35: No (gasto/IVA cortado en la exportación)
A36: CABRALES SALGADO ROLANDO ALBERTO | B36: 73571583 | C36: NDSE1724 | D36: 23359501 OTROS | E36: 79000 | F36: 79000 | G36: =IF(AND(ISNUMBER(E36),ISNUMBER(F36)),E36-F36,"No disponible") -> 0 | H36: Retenciones (crédito): 0.00 | Gasto/otros: No disponible (líneas fuera del archivo exportado) | I36: Aprobado con notificación (Documento soporte con no obligados, Emitido) | J36: Presente en el auxiliar (el archivo no trae columna de estado; se infiere Contabilizado) | K36: El lado proveedor + retenciones coincide exacto con la DIAN, pero las líneas de gasto/IVA no están completas en el Journal exportado (el archivo se corta en la fila 16.383); no se puede confirmar la suma de conceptos. | L36: — | M36: INFORMACIÓN INSUFICIENTE | N36: DIAN | O36: 001-DSE-00001724 | P36: 7530 | Q36: referencia | R36: No (gasto/IVA cortado en la exportación)
A37: CABRALES SALGADO ROLANDO ALBERTO | B37: 73571583 | C37: NDSE1725 | D37: 23359501 OTROS | E37: 119000 | F37: 119000 | G37: =IF(AND(ISNUMBER(E37),ISNUMBER(F37)),E37-F37,"No disponible") -> 0 | H37: Retenciones (crédito): 0.00 | Gasto/otros: No disponible (líneas fuera del archivo exportado) | I37: Aprobado con notificación (Documento soporte con no obligados, Emitido) | J37: Presente en el auxiliar (el archivo no trae columna de estado; se infiere Contabilizado) | K37: El lado proveedor + retenciones coincide exacto con la DIAN, pero las líneas de gasto/IVA no están completas en el Journal exportado (el archivo se corta en la fila 16.383); no se puede confirmar la suma de conceptos. | L37: — | M37: INFORMACIÓN INSUFICIENTE | N37: DIAN | O37: 001-DSE-00001725 | P37: 7531 | Q37: referencia | R37: No (gasto/IVA cortado en la exportación)
A38: CABRALES SALGADO ROLANDO ALBERTO | B38: 73571583 | C38: NDSE1729 | D38: 23359501 OTROS | E38: 316000 | F38: 316000 | G38: =IF(AND(ISNUMBER(E38),ISNUMBER(F38)),E38-F38,"No disponible") -> 0 | H38: Retenciones (crédito): 0.00 | Gasto/otros: No disponible (líneas fuera del archivo exportado) | I38: Aprobado con notificación (Documento soporte con no obligados, Emitido) | J38: Presente en el auxiliar (el archivo no trae columna de estado; se infiere Contabilizado) | K38: El lado proveedor + retenciones coincide exacto con la DIAN, pero las líneas de gasto/IVA no están completas en el Journal exportado (el archivo se corta en la fila 16.383); no se puede confirmar la suma de conceptos. | L38: — | M38: INFORMACIÓN INSUFICIENTE | N38: DIAN | O38: 001-DSE-00001729 | P38: 7532 | Q38: referencia | R38: No (gasto/IVA cortado en la exportación)
A39: CALVACHE JARAMILLO LUIS MIGUEL | B39: 1144093853 | C39: NDSE1715 | D39: 23359501 OTROS | E39: 2400 | F39: 2400 | G39: =IF(AND(ISNUMBER(E39),ISNUMBER(F39)),E39-F39,"No disponible") -> 0 | H39: Retenciones (crédito): 0.00 | Gasto/otros: No disponible (líneas fuera del archivo exportado) | I39: Aprobado con notificación (Documento soporte con no obligados, Emitido) | J39: Presente en el auxiliar (el archivo no trae columna de estado; se infiere Contabilizado) | K39: El lado proveedor + retenciones coincide exacto con la DIAN, pero las líneas de gasto/IVA no están completas en el Journal exportado (el archivo se corta en la fila 16.383); no se puede confirmar la suma de conceptos. | L39: — | M39: INFORMACIÓN INSUFICIENTE | N39: DIAN | O39: 001-DSE-00001715 | P39: 7401 | Q39: número del comprobante | R39: No (gasto/IVA cortado en la exportación)
A40: CARTONES AMERICA S.A. CAME | B40: 860026759 | C40: 8200455422 | D40: 23359501 OTROS; 24081510 IVA TRANSITORIO COMPRAS 19% | E40: 6999152 | F40: 6999152 | G40: =IF(AND(ISNUMBER(E40),ISNUMBER(F40)),E40-F40,"No disponible") -> 0 | H40: IVA: 1,117,512.00 | Retenciones (crédito): 0.00 | Gasto/otros: No disponible (líneas fuera del archivo exportado) | I40: Aprobado con notificación (Factura electrónica, Recibido) | J40: Presente en el auxiliar (el archivo no trae columna de estado; se infiere Contabilizado) | K40: El lado proveedor + retenciones coincide exacto con la DIAN, pero las líneas de gasto/IVA no están completas en el Journal exportado (el archivo se corta en la fila 16.383); no se puede confirmar la suma de conceptos. | L40: — | M40: INFORMACIÓN INSUFICIENTE | N40: DIAN | O40: 001-FSC-00011382 | P40: 7729, 11114 | Q40: referencia | R40: No (gasto/IVA cortado en la exportación)
...

Sheet Pendientes de revisión manual
A1: Nombre del tercero | B1: NIT o identificación | C1: Número del documento | D1: Cuenta contable y auxiliar | E1: Valor total según la DIAN | F1: Valor total sumado en el Journal | G1: Diferencia (DIAN − Journal) | H1: Desglose de conceptos contables | I1: Estado en la DIAN | J1: Estado en el Journal | K1: Motivo por el cual queda pendiente | L1: Observaciones para revisión manual | M1: Clasificación | N1: Origen | O1: Comprobante(s) Journal | P1: Fila(s) en el Journal | Q1: Método de cruce | R1: Lado gasto/IVA completo en el Journal
A2: ACEVEDO JOSE NORBEY | B2: 6137792 | C2: NDSE1703 | D2: 23359501 OTROS; 23652507 SERVICIOS GENERALES (DECLARANTES) 4%; 23680203 DEMAS ACTIVIDADES SERVICIOS 10 X 1000 | E2: 289000 | F2: 289000 | G2: =IF(AND(ISNUMBER(E2),ISNUMBER(F2)),E2-F2,"No disponible") -> 0 | H2: Retenciones (crédito): 14,450.00 | Gasto/otros: No disponible (líneas fuera del archivo exportado) | I2: Aprobado con notificación (Documento soporte con no obligados, Emitido) | J2: Presente en el auxiliar (el archivo no trae columna de estado; se infiere Contabilizado) | K2: El lado proveedor + retenciones coincide exacto con la DIAN, pero las líneas de gasto/IVA no están completas en el Journal exportado (el archivo se corta en la fila 16.383); no se puede confirmar la suma de conceptos. | L2: — | M2: INFORMACIÓN INSUFICIENTE | N2: DIAN | O2: 001-DSE-00001703 | P2: 7510, 8236, 9198 | Q2: número del comprobante | R2: No (gasto/IVA cortado en la exportación)
A3: ADOCCIDENTE S.A.S. | B3: 805010086 | C3: FE1043 | D3: 23359501 OTROS; 23652507 SERVICIOS GENERALES (DECLARANTES) 4%; 23653002 BIENES INMUEBLES 3,5%; 24081513 IVA TRANSITORIO SERVICIOS 19% | E3: 17074120 | F3: 17074120 | G3: =IF(AND(ISNUMBER(E3),ISNUMBER(F3)),E3-F3,"No disponible") -> 0 | H3: IVA: 2,726,120.00 | Retenciones (crédito): 523,680.00 | Gasto/otros: No disponible (líneas fuera del archivo exportado) | I3: Aprobado con notificación (Factura electrónica, Recibido) | J3: Presente en el auxiliar (el archivo no trae columna de estado; se infiere Contabilizado) | K3: El lado proveedor + retenciones coincide exacto con la DIAN, pero las líneas de gasto/IVA no están completas en el Journal exportado (el archivo se corta en la fila 16.383); no se puede confirmar la suma de conceptos. | L3: — | M3: INFORMACIÓN INSUFICIENTE | N3: DIAN | O3: 001-FSC-00011343 | P3: 7642, 8252, 8326, 11263 | Q3: referencia | R3: No (gasto/IVA cortado en la exportación)
A4: AEROVIAS DE INTEGRACION REGIONAL S.A. | B4: 890704196 | C4: A3933 | D4: 23354501 TRANSPORTES, FLETES Y ACARREOS | E4: 939272 | F4: 939272 | G4: =IF(AND(ISNUMBER(E4),ISNUMBER(F4)),E4-F4,"No disponible") -> 0 | H4: Retenciones (crédito): 0.00 | Gasto/otros: No disponible (líneas fuera del archivo exportado) | I4: Aprobado con notificación (Nota de crédito electrónica, Recibido) | J4: Presente en el auxiliar (el archivo no trae columna de estado; se infiere Contabilizado) | K4: El lado proveedor + retenciones coincide exacto con la DIAN, pero las líneas de gasto/IVA no están completas en el Journal exportado (el archivo se corta en la fila 16.383); no se puede confirmar la suma de conceptos. | L4: La descripción del comprobante menciona ANULACIÓN: confirmar que no esté anulado. | M4: INFORMACIÓN INSUFICIENTE | N4: DIAN | O4: 001-NT-00012697 | P4: 7357 | Q4: texto/descripción | R4: No (gasto/IVA cortado en la exportación)
A5: AEROVIAS DE INTEGRACION REGIONAL S.A. | B5: 890704196 | C5: SPC44755 | D5: 23354501 TRANSPORTES, FLETES Y ACARREOS | E5: 13701380 | F5: 13701380 | G5: =IF(AND(ISNUMBER(E5),ISNUMBER(F5)),E5-F5,"No disponible") -> 0 | H5: Retenciones (crédito): 0.00 | Gasto/otros: No disponible (líneas fuera del archivo exportado) | I5: Aprobado con notificación (Factura electrónica, Recibido) | J5: Presente en el auxiliar (el archivo no trae columna de estado; se infiere Contabilizado) | K5: El lado proveedor + retenciones coincide exacto con la DIAN, pero las líneas de gasto/IVA no están completas en el Journal exportado (el archivo se corta en la fila 16.383); no se puede confirmar la suma de conceptos. | L5: — | M5: INFORMACIÓN INSUFICIENTE | N5: DIAN | O5: 001-FSC-00011436 | P5: 7353 | Q5: referencia | R5: No (gasto/IVA cortado en la exportación)
A6: AEROVIAS DE INTEGRACION REGIONAL S.A. | B6: 890704196 | C6: SPC45219 | D6: 23354501 TRANSPORTES, FLETES Y ACARREOS | E6: 4535050 | F6: 4535050 | G6: =IF(AND(ISNUMBER(E6),ISNUMBER(F6)),E6-F6,"No disponible") -> 0 | H6: Retenciones (crédito): 0.00 | Gasto/otros: No disponible (líneas fuera del archivo exportado) | I6: Aprobado con notificación (Factura electrónica, Recibido) | J6: Presente en el auxiliar (el archivo no trae columna de estado; se infiere Contabilizado) | K6: El lado proveedor + retenciones coincide exacto con la DIAN, pero las líneas de gasto/IVA no están completas en el Journal exportado (el archivo se corta en la fila 16.383); no se puede confirmar la suma de conceptos. | L6: — | M6: INFORMACIÓN INSUFICIENTE | N6: DIAN | O6: 001-FSC-00011580 | P6: 7356 | Q6: referencia | R6: No (gasto/IVA cortado en la exportación)
A7: AEROVIAS DE INTEGRACIÓN REGIONAL S.A. | B7: 890704196 | C7: EFCC4800912 | D7: 23354501 TRANSPORTES, FLETES Y ACARREOS; 24081513 IVA TRANSITORIO SERVICIOS 19% | E7: 3317339 | F7: 3317399 | G7: =IF(AND(ISNUMBER(E7),ISNUMBER(F7)),E7-F7,"No disponible") -> -60 | H7: IVA: 521,750.00 | Retenciones (crédito): 0.00 | Gasto/otros: No disponible (líneas fuera del archivo exportado) | I7: Aprobado con notificación (Documento equivalente - Transporte aéreo de pasajeros, Recibido) | J7: Presente en el auxiliar (el archivo no trae columna de estado; se infiere Contabilizado) | K7: El lado proveedor + retenciones del Journal no coincide con el total de la DIAN. | L7: — | M7: PENDIENTE | N7: DIAN | O7: 001-FSC-00011488 | P7: 7354, 11339 | Q7: referencia | R7: No (gasto/IVA cortado en la exportación)
A8: AEROVIAS DE INTEGRACIÓN REGIONAL S.A. | B8: 890704196 | C8: EFCC4858340 | D8: No disponible | E8: 417940 | F8: No encontrado | G8: =IF(AND(ISNUMBER(E8),ISNUMBER(F8)),E8-F8,"No disponible") -> No disponible | H8: No disponible | I8: Aprobado con notificación (Documento equivalente - Transporte aéreo de pasajeros, Recibido) | J8: No encontrado | K8: No se encontró el documento en el Journal (el tercero sí tiene otros movimientos). | L8: El tercero aparece en el Journal pero ninguna línea cita este folio ni coincide su valor. | M8: PENDIENTE | N8: DIAN | O8: No encontrado | Q8: No encontrado | R8: No disponible
A9: AEROVIAS DEL CONTINENTE AMERICANO, S.A. AVIANCA - COLOMBIA | B9: 890100577 | C9: TQT26949290 | D9: 23359501 OTROS; 24081513 IVA TRANSITORIO SERVICIOS 19% | E9: 553160 | F9: 553160 | G9: =IF(AND(ISNUMBER(E9),ISNUMBER(F9)),E9-F9,"No disponible") -> 0 | H9: IVA: 84,360.00 | Retenciones (crédito): 0.00 | Gasto/otros: No disponible (líneas fuera del archivo exportado) | I9: Aprobado con notificación (Factura electrónica, Recibido) | J9: Presente en el auxiliar (el archivo no trae columna de estado; se infiere Contabilizado) | K9: El lado proveedor + retenciones coincide exacto con la DIAN, pero las líneas de gasto/IVA no están completas en el Journal exportado (el archivo se corta en la fila 16.383); no se puede confirmar la suma de conceptos. | L9: — | M9: INFORMACIÓN INSUFICIENTE | N9: DIAN | O9: 001-FSC-00011450 | P9: 7747, 11304 | Q9: referencia | R9: No (gasto/IVA cortado en la exportación)
A10: AGENCIA DE ADUANAS SANTIAGO RICO & BAÑOL LTDA. NIVEL 4 | B10: 827000059 | C10: SRFE804 | D10: 23359501 OTROS; 23652507 SERVICIOS GENERALES (DECLARANTES) 4% | E10: 450000 | F10: 450000 | G10: =IF(AND(ISNUMBER(E10),ISNUMBER(F10)),E10-F10,"No disponible") -> 0 | H10: Retenciones (crédito): 18,000.00 | Gasto/otros: No disponible (líneas fuera del archivo exportado) | I10: Aprobado con notificación (Factura electrónica, Recibido) | J10: Presente en el auxiliar (el archivo no trae columna de estado; se infiere Contabilizado) | K10: El lado proveedor + retenciones coincide exacto con la DIAN, pero las líneas de gasto/IVA no están completas en el Journal exportado (el archivo se corta en la fila 16.383); no se puede confirmar la suma de conceptos. | L10: — | M10: INFORMACIÓN INSUFICIENTE | N10: DIAN | O10: 001-FSC-00011385 | P10: 7680, 8256 | Q10: referencia | R10: No (gasto/IVA cortado en la exportación)
A11: AGENCIA DE ADUANAS SANTIAGO RICO & BAÑOL LTDA. NIVEL 4 | B11: 827000059 | C11: SRFE817 | D11: 23359501 OTROS; 23652507 SERVICIOS GENERALES (DECLARANTES) 4%; 26952001 PARA OPERACION | E11: 450000 | F11: 449999 | G11: =IF(AND(ISNUMBER(E11),ISNUMBER(F11)),E11-F11,"No disponible") -> 1 | H11: Otros conceptos: 449,999.00 | Retenciones (crédito): 18,000.00 | I11: Aprobado con notificación (Factura electrónica, Recibido) | J11: Presente en el auxiliar (el archivo no trae columna de estado; se infiere Contabilizado) | K11: La suma de los conceptos contables no coincide con el total de la DIAN. | L11: — | M11: PENDIENTE | N11: DIAN | O11: 001-CC-00023131 | P11: 7683, 8258, 12538 | Q11: referencia | R11: Sí
A12: ALMACEN LAS GEMELAS SAS | B12: 901849101 | C12: FE2169 | D12: 23359501 OTROS; 23654002 COMPRAS GENERALES 2,5%; 24081510 IVA TRANSITORIO COMPRAS 19% | E12: 792000.02 | F12: 792000 | G12: =IF(AND(ISNUMBER(E12),ISNUMBER(F12)),E12-F12,"No disponible") -> 0.02 | H12: IVA: 126,454.00 | Retenciones (crédito): 16,639.00 | Gasto/otros: No disponible (líneas fuera del archivo exportado) | I12: Aprobado con notificación (Factura electrónica, Recibido) | J12: Presente en el auxiliar (el archivo no trae columna de estado; se infiere Contabilizado) | K12: El lado proveedor + retenciones del Journal no coincide con el total de la DIAN. | L12: — | M12: PENDIENTE | N12: DIAN | O12: 001-FSC-00011456 | P12: 8028, 8415, 11207 | Q12: referencia | R12: No (gasto/IVA cortado en la exportación)
A13: ALMACENES ÉXITO S.A | B13: 890900608 | C13: RC06172758 | D13: 23359501 OTROS | E13: 37080 | F13: 37080 | G13: =IF(AND(ISNUMBER(E13),ISNUMBER(F13)),E13-F13,"No disponible") -> 0 | H13: Retenciones (crédito): 0.00 | Gasto/otros: No disponible (líneas fuera del archivo exportado) | I13: Aprobado con notificación (Factura electrónica, Recibido) | J13: Presente en el auxiliar (el archivo no trae columna de estado; se infiere Contabilizado) | K13: El lado proveedor + retenciones coincide exacto con la DIAN, pero las líneas de gasto/IVA no están completas en el Journal exportado (el archivo se corta en la fila 16.383); no se puede confirmar la suma de conceptos. | L13: — | M13: INFORMACIÓN INSUFICIENTE | N13: DIAN | O13: 001-FSC-00011592 | P13: 7822 | Q13: referencia | R13: No (gasto/IVA cortado en la exportación)
A14: ALMEIDA BACCA EDWARD ALEXANDER | B14: 16928075 | C14: FE681 | D14: No disponible | E14: 601985.3 | F14: No encontrado | G14: =IF(AND(ISNUMBER(E14),ISNUMBER(F14)),E14-F14,"No disponible") -> No disponible | H14: No disponible | I14: Aprobado con notificación (Factura electrónica, Recibido) | J14: No encontrado | K14: El tercero no aparece en el Journal. | L14: NIT sin movimientos en el archivo del Journal. | M14: PENDIENTE | N14: DIAN | O14: No encontrado | Q14: No encontrado | R14: No disponible
A15: ANILLANDO CALI LTDA | B15: 800038947 | C15: PFS10547 | D15: 22050501 PROVEEDORES NACIONALES; 24081510 IVA TRANSITORIO COMPRAS 19% | E15: 138900 | F15: 138900 | G15: =IF(AND(ISNUMBER(E15),ISNUMBER(F15)),E15-F15,"No disponible") -> 0 | H15: IVA: 22,177.00 | Retenciones (crédito): 0.00 | Gasto/otros: No disponible (líneas fuera del archivo exportado) | I15: Aprobado con notificación (Factura electrónica, Recibido) | J15: Presente en el auxiliar (el archivo no trae columna de estado; se infiere Contabilizado) | K15: El lado proveedor + retenciones coincide exacto con la DIAN, pero las líneas de gasto/IVA no están completas en el Journal exportado (el archivo se corta en la fila 16.383); no se puede confirmar la suma de conceptos. | L15: — | M15: INFORMACIÓN INSUFICIENTE | N15: DIAN | O15: 001-FSC-00011410 | P15: 7203, 11063 | Q15: referencia | R15: No (gasto/IVA cortado en la exportación)
A16: APONTE CASTILLO CARLOS DANIEL | B16: 1010204688 | C16: 422 | D16: 13309501 OTROS; 23359501 OTROS; 23654002 COMPRAS GENERALES 2,5%; 24081510 IVA TRANSITORIO COMPRAS 19% | E16: 6961500 | F16: 3553875 | G16: =IF(AND(ISNUMBER(E16),ISNUMBER(F16)),E16-F16,"No disponible") -> 3407625 | H16: IVA: 1,111,500.00 | Otros conceptos: -3,407,625.00 | Retenciones (crédito): 146,250.00 | Gasto/otros: No disponible (líneas fuera del archivo exportado) | I16: Aprobado con notificación (Factura electrónica, Recibido) | J16: Presente en el auxiliar (el archivo no trae columna de estado; se infiere Contabilizado) | K16: El lado proveedor + retenciones del Journal no coincide con el total de la DIAN. | L16: — | M16: PENDIENTE | N16: DIAN | O16: 001-FSC-00011398 | P16: 3306, 7373, 7374, 8332, 11047 | Q16: referencia | R16: No (gasto/IVA cortado en la exportación)
A17: AQUASISTEMAS DEL CARIBE S.A.S | B17: 802018827 | C17: FE232 | D17: 23359501 OTROS; 23654002 COMPRAS GENERALES 2,5% | E17: 561300 | F17: 561300 | G17: =IF(AND(ISNUMBER(E17),ISNUMBER(F17)),E17-F17,"No disponible") -> 0 | H17: Retenciones (crédito): 14,033.00 | Gasto/otros: No disponible (líneas fuera del archivo exportado) | I17: Aprobado con notificación (Factura electrónica, Recibido) | J17: Presente en el auxiliar (el archivo no trae columna de estado; se infiere Contabilizado) | K17: El lado proveedor + retenciones coincide exacto con la DIAN, pero las líneas de gasto/IVA no están completas en el Journal exportado (el archivo se corta en la fila 16.383); no se puede confirmar la suma de conceptos. | L17: — | M17: INFORMACIÓN INSUFICIENTE | N17: DIAN | O17: 001-FSC-00011582 | P17: 7637, 8367 | Q17: referencia | R17: No (gasto/IVA cortado en la exportación)
A18: ARIAS GLORIA PATRICIA | B18: 31411095 | C18: NDSE1700 | D18: 23359501 OTROS; 23654002 COMPRAS GENERALES 2,5%; 23680302 DEMAS ACTIVIDADES COMERCIALES 7,7 X 1000 | E18: 1620000 | F18: 1620000 | G18: =IF(AND(ISNUMBER(E18),ISNUMBER(F18)),E18-F18,"No disponible") -> 0 | H18: Retenciones (crédito): 52,974.00 | Gasto/otros: No disponible (líneas fuera del archivo exportado) | I18: Aprobado con notificación (Documento soporte con no obligados, Emitido) | J18: Presente en el auxiliar (el archivo no trae columna de estado; se infiere Contabilizado) | K18: El lado proveedor + retenciones coincide exacto con la DIAN, pero las líneas de gasto/IVA no están completas en el Journal exportado (el archivo se corta en la fila 16.383); no se puede confirmar la suma de conceptos. | L18: — | M18: INFORMACIÓN INSUFICIENTE | N18: DIAN | O18: 001-DSE-00001700 | P18: 7458, 8344, 9261 | Q18: referencia | R18: No (gasto/IVA cortado en la exportación)
A19: ARIAS GLORIA PATRICIA | B19: 31411095 | C19: NDSE1708 | D19: 23359501 OTROS; 23654002 COMPRAS GENERALES 2,5%; 23680203 DEMAS ACTIVIDADES SERVICIOS 10 X 1000 | E19: 3000000 | F19: 3000000 | G19: =IF(AND(ISNUMBER(E19),ISNUMBER(F19)),E19-F19,"No disponible") -> 0 | H19: Retenciones (crédito): 105,000.00 | Gasto/otros: No disponible (líneas fuera del archivo exportado) | I19: Aprobado con notificación (Documento soporte con no obligados, Emitido) | J19: Presente en el auxiliar (el archivo no trae columna de estado; se infiere Contabilizado) | K19: El lado proveedor + retenciones coincide exacto con la DIAN, pero las líneas de gasto/IVA no están completas en el Journal exportado (el archivo se corta en la fila 16.383); no se puede confirmar la suma de conceptos. | L19: — | M19: INFORMACIÓN INSUFICIENTE | N19: DIAN | O19: 001-DSE-00001708 | P19: 7460, 7461, 8345, 9195 | Q19: referencia | R19: No (gasto/IVA cortado en la exportación)
A20: ARIAS GLORIA PATRICIA | B20: 31411095 | C20: NDSE1734 | D20: 23359501 OTROS; 23652507 SERVICIOS GENERALES (DECLARANTES) 4%; 23680203 DEMAS ACTIVIDADES SERVICIOS 10 X 1000; 51055101 DOTACION Y SUMINISTRO A TRABAJADORES | E20: 636500 | F20: 636500 | G20: =IF(AND(ISNUMBER(E20),ISNUMBER(F20)),E20-F20,"No disponible") -> 0 | H20: Gastos: 38,000.00 | Retenciones (crédito): 31,825.00 | Gasto/otros: No disponible (líneas fuera del archivo exportado) | I20: Aprobado con notificación (Documento soporte con no obligados, Emitido) | J20: Presente en el auxiliar (el archivo no trae columna de estado; se infiere Contabilizado) | K20: El lado proveedor + retenciones coincide exacto con la DIAN, pero las líneas de gasto/IVA no están completas en el Journal exportado (el archivo se corta en la fila 16.383); no se puede confirmar la suma de conceptos. | L20: — | M20: INFORMACIÓN INSUFICIENTE | N20: DIAN | O20: 001-DSE-00001734 | P20: 7464, 8234, 9196, 16105 | Q20: referencia | R20: No (gasto/IVA cortado en la exportación)
A21: AZUL RESTAURANT AIRPORT | B21: 79308344 | C21: PAZ6314 | D21: 23359501 OTROS | E21: 24000 | F21: 24000 | G21: =IF(AND(ISNUMBER(E21),ISNUMBER(F21)),E21-F21,"No disponible") -> 0 | H21: Retenciones (crédito): 0.00 | Gasto/otros: No disponible (líneas fuera del archivo exportado) | I21: Aprobado con notificación (Factura electrónica, Recibido) | J21: Presente en el auxiliar (el archivo no trae columna de estado; se infiere Contabilizado) | K21: Coincide el NIT y el valor exacto, pero ninguna línea del Journal cita el número del documento; no se puede identificar con certeza. | L21: — | M21: INFORMACIÓN INSUFICIENTE | N21: DIAN | O21: 001-FSC-00011438 | P21: 7540 | Q21: NIT + valor (sin folio) | R21: No (gasto/IVA cortado en la exportación)
A22: AZUL RESTAURANT AIRPORT | B22: 79308344 | C22: PAZ6315 | D22: 23359501 OTROS | E22: 26000 | F22: 26000 | G22: =IF(AND(ISNUMBER(E22),ISNUMBER(F22)),E22-F22,"No disponible") -> 0 | H22: Retenciones (crédito): 0.00 | Gasto/otros: No disponible (líneas fuera del archivo exportado) | I22: Aprobado con notificación (Factura electrónica, Recibido) | J22: Presente en el auxiliar (el archivo no trae columna de estado; se infiere Contabilizado) | K22: El lado proveedor + retenciones coincide exacto con la DIAN, pero las líneas de gasto/IVA no están completas en el Journal exportado (el archivo se corta en la fila 16.383); no se puede confirmar la suma de conceptos. | L22: — | M22: INFORMACIÓN INSUFICIENTE | N22: DIAN | O22: 001-FSC-00011482 | P22: 7545 | Q22: referencia | R22: No (gasto/IVA cortado en la exportación)
A23: AZUL RESTAURANT AIRPORT | B23: 79308344 | C23: PAZ6316 | D23: No disponible | E23: 10000 | F23: No encontrado | G23: =IF(AND(ISNUMBER(E23),ISNUMBER(F23)),E23-F23,"No disponible") -> No disponible | H23: No disponible | I23: Aprobado con notificación (Factura electrónica, Recibido) | J23: No encontrado | K23: No se encontró el documento en el Journal (el tercero sí tiene otros movimientos). | L23: El tercero aparece en el Journal pero ninguna línea cita este folio ni coincide su valor. | M23: PENDIENTE | N23: DIAN | O23: No encontrado | Q23: No encontrado | R23: No disponible
A24: BAL STUDIO SAS | B24: 901986829 | C24: FE2458 | D24: 22050501 PROVEEDORES NACIONALES; 23670501 IVA RET. COMPRAS RC 15%; 24081513 IVA TRANSITORIO SERVICIOS 19% | E24: 2023000 | F24: 2023000 | G24: =IF(AND(ISNUMBER(E24),ISNUMBER(F24)),E24-F24,"No disponible") -> 0 | H24: IVA: 323,000.00 | Retenciones (crédito): 48,450.00 | Gasto/otros: No disponible (líneas fuera del archivo exportado) | I24: Aprobado con notificación (Factura electrónica, Recibido) | J24: Presente en el auxiliar (el archivo no trae columna de estado; se infiere Contabilizado) | K24: El lado proveedor + retenciones coincide exacto con la DIAN, pero las líneas de gasto/IVA no están completas en el Journal exportado (el archivo se corta en la fila 16.383); no se puede confirmar la suma de conceptos. | L24: — | M24: INFORMACIÓN INSUFICIENTE | N24: DIAN | O24: 001-FSC-00011483 | P24: 7250, 9156, 11501 | Q24: referencia | R24: No (gasto/IVA cortado en la exportación)
A25: BBVA SEGUROS COLOMBIA S.A. | B25: 800226098 | C25: FEAG1134986 | D25: 23359501 OTROS; 24081513 IVA TRANSITORIO SERVICIOS 19% | E25: 178364 | F25: 178364 | G25: =IF(AND(ISNUMBER(E25),ISNUMBER(F25)),E25-F25,"No disponible") -> 0 | H25: IVA: 28,478.00 | Retenciones (crédito): 0.00 | Gasto/otros: No disponible (líneas fuera del archivo exportado) | I25: Aprobado con notificación (Factura electrónica, Recibido) | J25: Presente en el auxiliar (el archivo no trae columna de estado; se infiere Contabilizado) | K25: El lado proveedor + retenciones coincide exacto con la DIAN, pero las líneas de gasto/IVA no están completas en el Journal exportado (el archivo se corta en la fila 16.383); no se puede confirmar la suma de conceptos. | L25: — | M25: INFORMACIÓN INSUFICIENTE | N25: DIAN | O25: 001-FSC-00011380 | P25: 7588, 11253 | Q25: referencia | R25: No (gasto/IVA cortado en la exportación)
A26: BENEMERITO CUERPO DE BOMBEROS VOLUNTARIOS DE CALI | B26: 890399000 | C26: FK72753 | D26: 23359501 OTROS; 24081513 IVA TRANSITORIO SERVICIOS 19% | E26: 942994 | F26: 942994 | G26: =IF(AND(ISNUMBER(E26),ISNUMBER(F26)),E26-F26,"No disponible") -> 0 | H26: IVA: 150,562.00 | Retenciones (crédito): 0.00 | Gasto/otros: No disponible (líneas fuera del archivo exportado) | I26: Aprobado con notificación (Factura electrónica, Recibido) | J26: Presente en el auxiliar (el archivo no trae columna de estado; se infiere Contabilizado) | K26: El lado proveedor + retenciones coincide exacto con la DIAN, pero las líneas de gasto/IVA no están completas en el Journal exportado (el archivo se corta en la fila 16.383); no se puede confirmar la suma de conceptos. | L26: — | M26: INFORMACIÓN INSUFICIENTE | N26: DIAN | O26: 001-FSC-00011563 | P26: 7799, 11332 | Q26: referencia | R26: No (gasto/IVA cortado en la exportación)
A27: BERMUDEZ RAMIREZ EUCARIO | B27: 16752920 | C27: NDSE1709 | D27: 22050501 PROVEEDORES NACIONALES; 23654002 COMPRAS GENERALES 2,5%; 23680302 DEMAS ACTIVIDADES COMERCIALES 7,7 X 1000 | E27: 11480000 | F27: 11480000 | G27: =IF(AND(ISNUMBER(E27),ISNUMBER(F27)),E27-F27,"No disponible") -> 0 | H27: Retenciones (crédito): 375,396.00 | Gasto/otros: No disponible (líneas fuera del archivo exportado) | I27: Aprobado con notificación (Documento soporte con no obligados, Emitido) | J27: Presente en el auxiliar (el archivo no trae columna de estado; se infiere Contabilizado) | K27: El lado proveedor + retenciones coincide exacto con la DIAN, pero las líneas de gasto/IVA no están completas en el Journal exportado (el archivo se corta en la fila 16.383); no se puede confirmar la suma de conceptos. | L27: — | M27: INFORMACIÓN INSUFICIENTE | N27: DIAN | O27: 001-DSE-00001709 | P27: 7195, 8335, 9255 | Q27: referencia | R27: No (gasto/IVA cortado en la exportación)
A28: BERNARDA VALENCIA MOYA | B28: 29951774 | C28: FEBV2769 | D28: 23359502 CUENTA PUENTE CAJA MENOR | E28: 20000 | F28: 20000 | G28: =IF(AND(ISNUMBER(E28),ISNUMBER(F28)),E28-F28,"No disponible") -> 0 | H28: Retenciones (crédito): 0.00 | Gasto/otros: No disponible (líneas fuera del archivo exportado) | I28: Aprobado con notificación (Factura electrónica, Recibido) | J28: Presente en el auxiliar (el archivo no trae columna de estado; se infiere Contabilizado) | K28: El lado proveedor + retenciones coincide exacto con la DIAN, pero las líneas de gasto/IVA no están completas en el Journal exportado (el archivo se corta en la fila 16.383); no se puede confirmar la suma de conceptos. | L28: — | M28: INFORMACIÓN INSUFICIENTE | N28: DIAN | O28: 001-FSC-00011557 | P28: 8084 | Q28: referencia | R28: No (gasto/IVA cortado en la exportación)
