Workbook

Sheet CAJAS REEMBOLSO 
C4: NATURAL SYSTEMS INTERNATIONAL SAS
C5: LEGALIZACION DE EDGAR YEPES
B7: NIT/CC | C7: PREFIJO | D7: NUMERO FACTURA | E7: FECHA FACTURA | F7: TERCERO | G7: CONCEPTO | H7: CENTRO DE COSTO | I7: SUB TOTAL GRAVADO | J7: SUB TOTAL SIN IVA | K7: IVA | L7: INC | M7: TOTAL
A9: 1 | D9: 292607292419034102111508 | E9: 29/01/2026 | F9: PANDA EXPRESS | G9: ALMUERZO | J9: 22.8 | K9: 1.6 | M9: =J9+K9 -> 24.4
A10: 2 | D10: 332405324915 | E10: 20/01/2026 | F10: BEST BUY | G10: CARGADOR DE COMPUTADOR | J10: 39.99 | K10: 2.8 | M10: =J10+K10 -> 42.79
A11: 3 | D11: 020381039221 | E11: 17/07/2026 | F11: THE HOME DEPOT | G11: HERRAMIENTAS | J11: 162.84 | K11: 10.36 | M11: =J11+K11 -> 173.2
A12: 4 | D12: 63438235160 | E12: 08/07/2026 | F12: THE HOME DEPOT | G12: MATERIALES DE CONTRUCCION | J12: 249.36 | K12: 17.46 | M12: =J12+K12 -> 266.82
A13: 5 | D13: 990032327006800009062626 | E13: 26/06/2026 | F13: IKEA | G13: FORRO DE COLCHON Y CUBIERTOS | J13: 28.98 | K13: 2.03 | M13: =J13+K13 -> 31.01
A14: 6 | D14: SHVU28 | E14: 46215 | F14: HOLLYWOOD FL | G14: PARQUEADERO | J14: 4.5 | M14: =J14+K14 -> 4.5
A15: 7 | D15: 5980203649 | E15: 46220 | F15: COSTCO | G15: MERCADO | J15: 13.99 | M15: =J15+K15 -> 13.99
A16: 8 | D16: 02057SR039301 | E16: 46230 | F16: PUBLIX | G16: MERCADO | J16: 7.28 | K16: 0.51 | M16: =J16+K16 -> 7.79
A17: 9 | D17: 05300730000031184821 | E17: 46233 | F17: STEAK N SHAKE | G17: ALMUERZO | J17: 9.68 | K17: 0.68 | M17: =J17+K17 -> 10.36
A18: 10 | D18: 89890723601011 | E18: 46229 | F18: DOLLAR TREE | G18: MERCADO | J18: 4.5 | K18: 0.32 | M18: =J18+K18 -> 4.82
A19: 11 | D19: 702771302108429 | E19: 46231 | F19: BURGER KING | G19: COMIDA | J19: 12.99 | K19: 0.91 | M19: =J19+K19 -> 13.9
A20: 12 | D20: 63248 | E20: 46221 | F20: TRADER JOES | G20: MERCADO | J20: 12.27 | M20: =J20+K20 -> 12.27
A21: 13 | D21: 164 | E21: 46232 | F21: CHASE | G21: PAGO DE ENERGIA | J21: 160.44 | M21: =J21+K21 -> 160.44
A22: 14 | D22: 4730 FA04 | E22: 45880 | F22: ALDI | G22: MERCADO | J22: 57.67 | K22: 0.85 | M22: =J22+K22 -> 58.52
A23: 15 | D23: 56869813583243057951 | E23: 46217 | F23: WALMART | G23: MERCADO | J23: 40.3 | K23: 0.8 | M23: =J23+K23 -> 41.1
A24: 16 | D24: 9199337126 | E24: 46214 | F24: COSTCO | G24: MERCADO | J24: 26.99 | K24: 1.89 | M24: =J24+K24 -> 28.88
A25: 17 | D25: 91205225705 | E25: 46214 | F25: COSTCO | G25: MERCADO | J25: 69.03 | K25: 2.93 | M25: =J25+K25 -> 71.96
A26: 18 | D26: 91233213733 | E26: 46214 | F26: COSTCO | G26: ALMUERZO | J26: 3.49 | K26: 0.24 | M26: =J26+K26 -> 3.73
A27: 19 | D27: 6178081500794130 | E27: 46200 | F27: TARGET | G27: MERCADO | J27: 34.96 | K27: 2.17 | M27: =J27+K27 -> 37.13
A28: 20 | D28: 34870723602023 | E28: 46204 | F28: DOLLAR TREE | G28: MERCADO | J28: 7.5 | K28: 0.32 | M28: =J28+K28 -> 7.82
A29: 21 | D29: 49460723601012 | E29: 46214 | F29: DOLLAR TREE | G29: MERCADO | J29: 8.25 | K29: 0.21 | M29: =J29+K29 -> 8.46
A30: 22 | D30: 40065 | E30: 46234 | F30: CHURCHS | G30: ALMUERZO | J30: 11.28 | K30: 0.79 | M30: =J30+K30 -> 12.07
A31: 23 | D31: 306495 | E31: 46200 | F31: ASIAN CHAO | G31: ALMUERZO | J31: 13.99 | K31: 0.98 | M31: =J31+K31 -> 14.97
A32: 24 | D32: 02225275369 | E32: 46213 | F32: THE HOME DEPOT | G32: TRONILLOS Y TAB | J32: 31.8 | K32: 2.23 | M32: =J32+K32 -> 34.03
A33: 25 | D33: 02220002715449 | E33: 46213 | F33: THE HOME DEPOT | G33: ENCHUFES Y REGLETA | J33: 40.32 | K33: 2.82 | M33: =J33+K33 -> 43.14
A34: 26 | D34: 22043346110686495322 | E34: 46211 | F34: WALMART | G34: MERCADO | J34: 9.47 | M34: =J34+K34 -> 9.47
A35: 27 | D35: 199974 | E35: 46208 | F35: POLLO TROPICAL | G35: ALMUERZO | J35: 10.29 | K35: 0.72 | M35: =J35+K35 -> 11.01
A36: 28 | D36: 199977 | E36: 46208 | F36: POLLO TROPICAL | G36: ALMUERZO | J36: 4.79 | K36: 0.34 | M36: =J36+K36 -> 5.13
A37: 29 | D37: 233156733 | E37: 46212 | F37: COSTCO | G37: ALMUERZO | J37: 5.48 | K37: 0.38 | M37: =J37+K37 -> 5.86
A38: 30 | D38: 0354FS76 | E38: 46209 | F38: ALDI | G38: MERCADO | J38: 12.7 | K38: 0.01 | M38: =J38+K38 -> 12.71
A39: 31 | D39: 02225370259 | E39: 46212 | F39: THE HOME DEPOT | G39: MESA | J39: 38.2 | K39: 2.67 | M39: =J39+K39 -> 40.87
A40: 32 | D40: 2750FA04 | E40: 46231 | F40: ALDI | G40: MERCADO | J40: 9.96 | M40: =J40+K40 -> 9.96
A41: 33 | D41: 261171516654 | E41: 46232 | F41: WENDYS | G41: ALMUERZO | J41: 8 | K41: 0.56 | M41: =J41+K41 -> 8.56
A42: 34 | D42: 9930014904647 | E42: 46197 | F42: SEDANOS | G42: MERCADO | J42: 4.734 | K42: 0.2 | M42: =J42+K42 -> 4.934
A43: 35 | D43: 10314 | E43: 46198 | F43: CHIPOTLE | G43: ALMUERZO | J43: 13.45 | K43: 0.94 | M43: =J43+K43 -> 14.39
A44: 36 | D44: 76320971240197904112 | E44: 46201 | F44: WALMART | G44: ALMUERZO | J44: 41.05 | K44: 2.22 | M44: =J44+K44 -> 43.27
A45: 37 | D45: 91636664 | E45: 46195 | F45: COSTCO | G45: MERCADO | J45: 193.23 | K45: 3.78 | M45: =J45+K45 -> 197.01
...

Sheet Por tercero
A1: REEMBOLSO EDGAR YEPES — valores en DÓLARES (USD) por tercero; use + / − (o botones 1/2) para ver las facturas de cada tercero
D2: TOTAL GENERAL | E2: =SUMIF($H$5:$H$300,"TOTAL TERCERO",E5:E300) -> 2698.804 | F2: =SUMIF($H$5:$H$300,"TOTAL TERCERO",F5:F300) -> 83.07 | G2: =SUMIF($H$5:$H$300,"TOTAL TERCERO",G5:G300) -> 2781.874
A4: Tercero | B4: N° factura | C4: Fecha | D4: Concepto | E4: Subtotal sin IVA (USD) | F4: IVA (USD) | G4: Total (USD) | H4: Tipo / # facturas | I4: Ítem
A5: ALDI | B5: =COUNTIFS('CAJAS REEMBOLSO '!$F$9:$F$80,A5) -> 4 | E5: =SUMIFS('CAJAS REEMBOLSO '!$J$9:$J$80,'CAJAS REEMBOLSO '!$F$9:$F$80,$A5) -> 98.16 | F5: =SUMIFS('CAJAS REEMBOLSO '!$K$9:$K$80,'CAJAS REEMBOLSO '!$F$9:$F$80,$A5) -> 0.86 | G5: =SUMIFS('CAJAS REEMBOLSO '!$M$9:$M$80,'CAJAS REEMBOLSO '!$F$9:$F$80,$A5) -> 99.02 | H5: TOTAL TERCERO
A6: ALDI | B6: 4730 FA04 | C6: 45880 | D6: MERCADO | E6: =N('CAJAS REEMBOLSO '!J22) -> 57.67 | F6: =N('CAJAS REEMBOLSO '!K22) -> 0.85 | G6: ='CAJAS REEMBOLSO '!M22 -> 58.52 | H6: Factura | I6: 14
A7: ALDI | B7: 8303FS76 | C7: 46199 | D7: MERCADO | E7: =N('CAJAS REEMBOLSO '!J54) -> 17.83 | F7: =N('CAJAS REEMBOLSO '!K54) -> 0 | G7: ='CAJAS REEMBOLSO '!M54 -> 17.83 | H7: Factura | I7: 46
A8: ALDI | B8: 0354FS76 | C8: 46209 | D8: MERCADO | E8: =N('CAJAS REEMBOLSO '!J38) -> 12.7 | F8: =N('CAJAS REEMBOLSO '!K38) -> 0.01 | G8: ='CAJAS REEMBOLSO '!M38 -> 12.71 | H8: Factura | I8: 30
A9: ALDI | B9: 2750FA04 | C9: 46231 | D9: MERCADO | E9: =N('CAJAS REEMBOLSO '!J40) -> 9.96 | F9: =N('CAJAS REEMBOLSO '!K40) -> 0 | G9: ='CAJAS REEMBOLSO '!M40 -> 9.96 | H9: Factura | I9: 32
A10: ASIAN CHAO | B10: =COUNTIFS('CAJAS REEMBOLSO '!$F$9:$F$80,A10) -> 1 | E10: =SUMIFS('CAJAS REEMBOLSO '!$J$9:$J$80,'CAJAS REEMBOLSO '!$F$9:$F$80,$A10) -> 13.99 | F10: =SUMIFS('CAJAS REEMBOLSO '!$K$9:$K$80,'CAJAS REEMBOLSO '!$F$9:$F$80,$A10) -> 0.98 | G10: =SUMIFS('CAJAS REEMBOLSO '!$M$9:$M$80,'CAJAS REEMBOLSO '!$F$9:$F$80,$A10) -> 14.97 | H10: TOTAL TERCERO
A11: ASIAN CHAO | B11: 306495 | C11: 46200 | D11: ALMUERZO | E11: =N('CAJAS REEMBOLSO '!J31) -> 13.99 | F11: =N('CAJAS REEMBOLSO '!K31) -> 0.98 | G11: ='CAJAS REEMBOLSO '!M31 -> 14.97 | H11: Factura | I11: 23
A12: BEST BUY | B12: =COUNTIFS('CAJAS REEMBOLSO '!$F$9:$F$80,A12) -> 1 | E12: =SUMIFS('CAJAS REEMBOLSO '!$J$9:$J$80,'CAJAS REEMBOLSO '!$F$9:$F$80,$A12) -> 39.99 | F12: =SUMIFS('CAJAS REEMBOLSO '!$K$9:$K$80,'CAJAS REEMBOLSO '!$F$9:$F$80,$A12) -> 2.8 | G12: =SUMIFS('CAJAS REEMBOLSO '!$M$9:$M$80,'CAJAS REEMBOLSO '!$F$9:$F$80,$A12) -> 42.79 | H12: TOTAL TERCERO
A13: BEST BUY | B13: 332405324915 | C13: 46042 | D13: CARGADOR DE COMPUTADOR | E13: =N('CAJAS REEMBOLSO '!J10) -> 39.99 | F13: =N('CAJAS REEMBOLSO '!K10) -> 2.8 | G13: ='CAJAS REEMBOLSO '!M10 -> 42.79 | H13: Factura | I13: 2
A14: BRANDS MART | B14: =COUNTIFS('CAJAS REEMBOLSO '!$F$9:$F$80,A14) -> 1 | E14: =SUMIFS('CAJAS REEMBOLSO '!$J$9:$J$80,'CAJAS REEMBOLSO '!$F$9:$F$80,$A14) -> 19.98 | F14: =SUMIFS('CAJAS REEMBOLSO '!$K$9:$K$80,'CAJAS REEMBOLSO '!$F$9:$F$80,$A14) -> 1.4 | G14: =SUMIFS('CAJAS REEMBOLSO '!$M$9:$M$80,'CAJAS REEMBOLSO '!$F$9:$F$80,$A14) -> 21.38 | H14: TOTAL TERCERO
A15: BRANDS MART | B15: 1070260002007000000 | C15: 46208 | D15: SANDUCHERA | E15: =N('CAJAS REEMBOLSO '!J51) -> 19.98 | F15: =N('CAJAS REEMBOLSO '!K51) -> 1.4 | G15: ='CAJAS REEMBOLSO '!M51 -> 21.38 | H15: Factura | I15: 43
A16: BURGER KING | B16: =COUNTIFS('CAJAS REEMBOLSO '!$F$9:$F$80,A16) -> 1 | E16: =SUMIFS('CAJAS REEMBOLSO '!$J$9:$J$80,'CAJAS REEMBOLSO '!$F$9:$F$80,$A16) -> 12.99 | F16: =SUMIFS('CAJAS REEMBOLSO '!$K$9:$K$80,'CAJAS REEMBOLSO '!$F$9:$F$80,$A16) -> 0.91 | G16: =SUMIFS('CAJAS REEMBOLSO '!$M$9:$M$80,'CAJAS REEMBOLSO '!$F$9:$F$80,$A16) -> 13.9 | H16: TOTAL TERCERO
A17: BURGER KING | B17: 702771302108429 | C17: 46231 | D17: COMIDA | E17: =N('CAJAS REEMBOLSO '!J19) -> 12.99 | F17: =N('CAJAS REEMBOLSO '!K19) -> 0.91 | G17: ='CAJAS REEMBOLSO '!M19 -> 13.9 | H17: Factura | I17: 11
A18: CHASE | B18: =COUNTIFS('CAJAS REEMBOLSO '!$F$9:$F$80,A18) -> 1 | E18: =SUMIFS('CAJAS REEMBOLSO '!$J$9:$J$80,'CAJAS REEMBOLSO '!$F$9:$F$80,$A18) -> 160.44 | F18: =SUMIFS('CAJAS REEMBOLSO '!$K$9:$K$80,'CAJAS REEMBOLSO '!$F$9:$F$80,$A18) -> 0 | G18: =SUMIFS('CAJAS REEMBOLSO '!$M$9:$M$80,'CAJAS REEMBOLSO '!$F$9:$F$80,$A18) -> 160.44 | H18: TOTAL TERCERO
A19: CHASE | B19: 164 | C19: 46232 | D19: PAGO DE ENERGIA | E19: =N('CAJAS REEMBOLSO '!J21) -> 160.44 | F19: =N('CAJAS REEMBOLSO '!K21) -> 0 | G19: ='CAJAS REEMBOLSO '!M21 -> 160.44 | H19: Factura | I19: 13
A20: CHIPOTLE | B20: =COUNTIFS('CAJAS REEMBOLSO '!$F$9:$F$80,A20) -> 2 | E20: =SUMIFS('CAJAS REEMBOLSO '!$J$9:$J$80,'CAJAS REEMBOLSO '!$F$9:$F$80,$A20) -> 31.4 | F20: =SUMIFS('CAJAS REEMBOLSO '!$K$9:$K$80,'CAJAS REEMBOLSO '!$F$9:$F$80,$A20) -> 2.2 | G20: =SUMIFS('CAJAS REEMBOLSO '!$M$9:$M$80,'CAJAS REEMBOLSO '!$F$9:$F$80,$A20) -> 33.6 | H20: TOTAL TERCERO
A21: CHIPOTLE | B21: 10314 | C21: 46198 | D21: ALMUERZO | E21: =N('CAJAS REEMBOLSO '!J43) -> 13.45 | F21: =N('CAJAS REEMBOLSO '!K43) -> 0.94 | G21: ='CAJAS REEMBOLSO '!M43 -> 14.39 | H21: Factura | I21: 35
A22: CHIPOTLE | B22: 220 | C22: 46201 | D22: ALMUERZO | E22: =N('CAJAS REEMBOLSO '!J53) -> 17.95 | F22: =N('CAJAS REEMBOLSO '!K53) -> 1.26 | G22: ='CAJAS REEMBOLSO '!M53 -> 19.21 | H22: Factura | I22: 45
A23: CHURCHS | B23: =COUNTIFS('CAJAS REEMBOLSO '!$F$9:$F$80,A23) -> 1 | E23: =SUMIFS('CAJAS REEMBOLSO '!$J$9:$J$80,'CAJAS REEMBOLSO '!$F$9:$F$80,$A23) -> 11.28 | F23: =SUMIFS('CAJAS REEMBOLSO '!$K$9:$K$80,'CAJAS REEMBOLSO '!$F$9:$F$80,$A23) -> 0.79 | G23: =SUMIFS('CAJAS REEMBOLSO '!$M$9:$M$80,'CAJAS REEMBOLSO '!$F$9:$F$80,$A23) -> 12.07 | H23: TOTAL TERCERO
A24: CHURCHS | B24: 40065 | C24: 46234 | D24: ALMUERZO | E24: =N('CAJAS REEMBOLSO '!J30) -> 11.28 | F24: =N('CAJAS REEMBOLSO '!K30) -> 0.79 | G24: ='CAJAS REEMBOLSO '!M30 -> 12.07 | H24: Factura | I24: 22
A25: COSTCO | B25: =COUNTIFS('CAJAS REEMBOLSO '!$F$9:$F$80,A25) -> 12 | E25: =SUMIFS('CAJAS REEMBOLSO '!$J$9:$J$80,'CAJAS REEMBOLSO '!$F$9:$F$80,$A25) -> 528.88 | F25: =SUMIFS('CAJAS REEMBOLSO '!$K$9:$K$80,'CAJAS REEMBOLSO '!$F$9:$F$80,$A25) -> 14.14 | G25: =SUMIFS('CAJAS REEMBOLSO '!$M$9:$M$80,'CAJAS REEMBOLSO '!$F$9:$F$80,$A25) -> 543.02 | H25: TOTAL TERCERO
A26: COSTCO | B26: 91636664 | C26: 46195 | D26: MERCADO | E26: =N('CAJAS REEMBOLSO '!J45) -> 193.23 | F26: =N('CAJAS REEMBOLSO '!K45) -> 3.78 | G26: ='CAJAS REEMBOLSO '!M45 -> 197.01 | H26: Factura | I26: 37
A27: COSTCO | B27: 91234476734 | C27: 46195 | D27: ALMUERZO | E27: =N('CAJAS REEMBOLSO '!J46) -> 3.49 | F27: =N('CAJAS REEMBOLSO '!K46) -> 0.24 | G27: ='CAJAS REEMBOLSO '!M46 -> 3.73 | H27: Factura | I27: 38
A28: COSTCO | B28: 911120612 | C28: 46204 | D28: MERCADO | E28: =N('CAJAS REEMBOLSO '!J47) -> 20.87 | F28: =N('CAJAS REEMBOLSO '!K47) -> 0.49 | G28: ='CAJAS REEMBOLSO '!M47 -> 21.36 | H28: Factura | I28: 39
A29: COSTCO | B29: 91233178733 | C29: 46204 | D29: COMIDA | E29: =N('CAJAS REEMBOLSO '!J49) -> 2.49 | F29: =N('CAJAS REEMBOLSO '!K49) -> 0.17 | G29: ='CAJAS REEMBOLSO '!M49 -> 2.66 | H29: Factura | I29: 41
A30: COSTCO | B30: 91233120733 | C30: 46206 | D30: ALMUERZO | E30: =N('CAJAS REEMBOLSO '!J48) -> 3.49 | F30: =N('CAJAS REEMBOLSO '!K48) -> 0.24 | G30: ='CAJAS REEMBOLSO '!M48 -> 3.73 | H30: Factura | I30: 40
A31: COSTCO | B31: 233156733 | C31: 46212 | D31: ALMUERZO | E31: =N('CAJAS REEMBOLSO '!J37) -> 5.48 | F31: =N('CAJAS REEMBOLSO '!K37) -> 0.38 | G31: ='CAJAS REEMBOLSO '!M37 -> 5.86 | H31: Factura | I31: 29
A32: COSTCO | B32: 9199337126 | C32: 46214 | D32: MERCADO | E32: =N('CAJAS REEMBOLSO '!J24) -> 26.99 | F32: =N('CAJAS REEMBOLSO '!K24) -> 1.89 | G32: ='CAJAS REEMBOLSO '!M24 -> 28.88 | H32: Factura | I32: 16
A33: COSTCO | B33: 91205225705 | C33: 46214 | D33: MERCADO | E33: =N('CAJAS REEMBOLSO '!J25) -> 69.03 | F33: =N('CAJAS REEMBOLSO '!K25) -> 2.93 | G33: ='CAJAS REEMBOLSO '!M25 -> 71.96 | H33: Factura | I33: 17
A34: COSTCO | B34: 91233213733 | C34: 46214 | D34: ALMUERZO | E34: =N('CAJAS REEMBOLSO '!J26) -> 3.49 | F34: =N('CAJAS REEMBOLSO '!K26) -> 0.24 | G34: ='CAJAS REEMBOLSO '!M26 -> 3.73 | H34: Factura | I34: 18
A35: COSTCO | B35: 5980203649 | C35: 46220 | D35: MERCADO | E35: =N('CAJAS REEMBOLSO '!J15) -> 13.99 | F35: =N('CAJAS REEMBOLSO '!K15) -> 0 | G35: ='CAJAS REEMBOLSO '!M15 -> 13.99 | H35: Factura | I35: 7
A36: COSTCO | B36: 91205155705 | C36: 46227 | D36: MERCADO | E36: =N('CAJAS REEMBOLSO '!J57) -> 86.53 | F36: =N('CAJAS REEMBOLSO '!K57) -> 0.98 | G36: ='CAJAS REEMBOLSO '!M57 -> 87.51 | H36: Factura | I36: 49
A37: COSTCO | B37: 9197352 | C37: 46236 | D37: MERCADO | E37: =N('CAJAS REEMBOLSO '!J56) -> 99.8 | F37: =N('CAJAS REEMBOLSO '!K56) -> 2.8 | G37: ='CAJAS REEMBOLSO '!M56 -> 102.6 | H37: Factura | I37: 48
A38: COUNTRY TAX COLLECTOR | B38: =COUNTIFS('CAJAS REEMBOLSO '!$F$9:$F$80,A38) -> 2 | E38: =SUMIFS('CAJAS REEMBOLSO '!$J$9:$J$80,'CAJAS REEMBOLSO '!$F$9:$F$80,$A38) -> 63 | F38: =SUMIFS('CAJAS REEMBOLSO '!$K$9:$K$80,'CAJAS REEMBOLSO '!$F$9:$F$80,$A38) -> 0 | G38: =SUMIFS('CAJAS REEMBOLSO '!$M$9:$M$80,'CAJAS REEMBOLSO '!$F$9:$F$80,$A38) -> 63 | H38: TOTAL TERCERO
A39: COUNTRY TAX COLLECTOR | B39: 32386729 | C39: 46205 | D39: LICENCIA DRIVER | E39: =N('CAJAS REEMBOLSO '!J69) -> 6.25 | F39: =N('CAJAS REEMBOLSO '!K69) -> 0 | G39: ='CAJAS REEMBOLSO '!M69 -> 6.25 | H39: Factura | I39: 61
A40: COUNTRY TAX COLLECTOR | B40: 32384944 | C40: 46205 | D40: LICENCIA DRIVER | E40: =N('CAJAS REEMBOLSO '!J70) -> 56.75 | F40: =N('CAJAS REEMBOLSO '!K70) -> 0 | G40: ='CAJAS REEMBOLSO '!M70 -> 56.75 | H40: Factura | I40: 62
A41: DOLLAR TREE | B41: =COUNTIFS('CAJAS REEMBOLSO '!$F$9:$F$80,A41) -> 5 | E41: =SUMIFS('CAJAS REEMBOLSO '!$J$9:$J$80,'CAJAS REEMBOLSO '!$F$9:$F$80,$A41) -> 60.75 | F41: =SUMIFS('CAJAS REEMBOLSO '!$K$9:$K$80,'CAJAS REEMBOLSO '!$F$9:$F$80,$A41) -> 2.62 | G41: =SUMIFS('CAJAS REEMBOLSO '!$M$9:$M$80,'CAJAS REEMBOLSO '!$F$9:$F$80,$A41) -> 63.37 | H41: TOTAL TERCERO
...
