Workbook

Sheet FORMATO NOMINA
B1: SALARIO MÍNIMO | C1: 1750905 | D1: AUXILIO DE TRANSPORTE | G1: 249095
G2: NOMINA PARA PAGO DE SUELDOS | T2: DEPURACION PROCEDIMIENTO 1 - RETENCION POR SALARIOS
T3: TOTAL INGRESOS POR PAGOS LABORALES: | V3: =J7 -> 17900000
G4: PERIODO DE PAGO | J4: DEL | K4: 46143 | M4: AL | N4: 46173 | T4: (-) INGRESOS NO GRAVADOS:
B5: NOMBRE DEL EMPLEADO | C5: SUELDO BASICO | D5: DIAS | E5: DEVENGADO | K5: DEDUCCIONES | T5: Aportes obligatorios a salud (Sobre ingresos del mismo mes) | U5: =K7 -> 716000
E6: BASICO | F6: AUX. TRASP | G6: BONIFICACION | H6: H. E. Y RECARGOS | I6: INCAP. Y LIC. | J6: TOTAL DEVENG | K6: SALUD | L6: PENSIÓN | M6: FSP | N6: RETENCIÓN | O6: EMBARGOS | P6: COOPERATIVA | Q6: TOTAL DEDUCC | R6: NETO PAGADO | T6: Aportes obligatorios a pensión (Sobre ingresos del mismo mes) | U6: =L7+M7 -> 895000
B7: BERNARDO ROJAS | C7: 17600000 | D7: 30 | E7: =C7*D7/30 -> 17600000 | F7: =IF(C7<=2*$C$1,$G$1*D7/30,0) -> 0 | G7: 300000 | J7: =SUM(E7:I7) -> 17900000 | K7: =(J7-F7)*4% -> 716000 | L7: =(J7-F7)*4% -> 716000 | M7: =IF((J7-F7)>=4*$C$1,(J7-F7)*0.01,0) -> 179000 | N7: =U27 -> 1184000 | Q7: =SUM(K7:P7) -> 2795000 | R7: =J7-Q7 -> 15105000 | T7: Total Ingresos No Gravados | V7: =U5+U6 -> 1611000
B8: LEONARDO ROSAS | C8: 1900000 | D8: 14 | E8: =C8*D8/30 -> 886666.67 | F8: =IF(C8<=2*$C$1,$G$1*D8/30,0) -> 116244.33 | H8: =(C8*E37*E32/210)+(C8*I37*I32/210) -> 529285.71 | J8: =SUM(E8:I8) -> 1532196.7 | K8: =(J8-F8)*4% -> 56638.095 | L8: =(J8-F8)*4% -> 56638.095 | M8: =IF((J8-F8)>=4*$C$1,(J8-F8)*0.01,0) -> 0 | P8: 100000 | Q8: =SUM(K8:P8) -> 213276.19 | R8: =J8-Q8 -> 1318920.5 | T8: SUBTOTAL 1 = (TOTAL INGRESOS NETOS LABORALES DEL MES- TOTAL INGRESOS NO GRAVADOS) | V8: =V3-V7 -> 16289000
B9: GERARDO VALVERDE | C9: 2460000 | D9: 23 | E9: =C9*D9/30 -> 1886000 | F9: =IF(C9<=2*$C$1,$G$1*D9/30,0) -> 190972.83 | I9: =R33 -> 408544.5 | J9: =SUM(E9:I9) -> 2485517.3 | K9: =(J9-F9)*4% -> 91781.78 | L9: =(J9-F9)*4% -> 91781.78 | M9: =IF((J9-F9)>=4*$C$1,(J9-F9)*0.01,0) -> 0 | Q9: =SUM(K9:P9) -> 183563.56 | R9: =J9-Q9 -> 2301953.8 | T9: (-) DEDUCCIONES: | Y9: 16 | Z9: =$X$10*Y9 -> 837984 | AA9: Prepagada
B10: EDUARDO BLANCO | C10: =$C$1 -> 1750905 | D10: 25 | E10: =C10*D10/30 -> 1459087.5 | F10: =IF(C10<=2*$C$1,$G$1*D10/30,0) -> 207579.17 | H10: =C10*E37*E34/210 -> 253464.34 | I10: =R34 -> 291817.5 | J10: =SUM(E10:I10) -> 2211948.5 | K10: =(J10-F10)*4% -> 80174.774 | L10: =(J10-F10)*4% -> 80174.774 | M10: =IF((J10-F10)>=4*$C$1,(J10-F10)*0.01,0) -> 0 | Q10: =SUM(K10:P10) -> 160349.55 | R10: =J10-Q10 -> 2051599 | T10: Intereses en préstamos para adquisición de vivienda del trabajador, límite 100 UVT mensuales | U10: 980000 | X10: 52374 | Y10: 32 | Z10: =$X$10*Y10 -> 1675968 | AA10: Personas a C
B11: GILDARDO AMARILLA | C11: 1820000 | D11: 30 | E11: =C11*D11/30 -> 1820000 | F11: =IF(C11<=2*$C$1,$G$1*D11/30,0) -> 249095 | H11: =(C11*F37*F35/210)+(C11*H37*H35/210) -> 1031333.3 | J11: =SUM(E11:I11) -> 3100428.3 | K11: =(J11-F11)*4% -> 114053.33 | L11: =(J11-F11)*4% -> 114053.33 | M11: =IF((J11-F11)>=4*$C$1,(J11-F11)*0.01,0) -> 0 | O11: =(C11-$C$1)/5 -> 13819 | Q11: =SUM(K11:P11) -> 241925.67 | R11: =J11-Q11 -> 2858502.7 | T11: Pagos durante el año anterior por concepto de medicina prepagada, limite 16 UVT, mensuales | U11: 0 | Y11: 100 | Z11: =$X$10*Y11 -> 5237400 | AA11: Intereses V
B12: JASMIN PEÑALOZA | C12: 1930000 | D12: 18 | E12: =C12*D12/30 -> 1158000 | F12: =IF(C12<=2*$C$1,$G$1*D12/30,0) -> 149457 | I12: =R36 -> 772000 | J12: =SUM(E12:I12) -> 2079457 | K12: =(J12-F12)*4% -> 77200 | L12: =(J12-F12)*4% -> 77200 | M12: =IF((J12-F12)>=4*$C$1,(J12-F12)*0.01,0) -> 0 | Q12: =SUM(K12:P12) -> 154400 | R12: =J12-Q12 -> 1925057 | T12: Deducciones por concepto de dependientes o personas a cargo 10% limitados a 32 UVT mes | U12: =MIN(V3*0.1,$Z$10) -> 1675968
T13: Total Deducciones | V13: =SUM(U10:U12) -> 2655968
T14: (-) RENTAS EXENTAS
T15: Aportes voluntarios a los fondos de pensiones (hasta 30% del ingreso Bruto mensual, sin exceder 3.800 UVT al año) | U15: 0 | X15: AFC = Ahorro para el Fomento de la Construcción
T16: Aportes voluntarios a las cuentas de ahorro AFC y AVC (Limite igual a los aportes voluntarios a pensión) | U16: 0 | X16: AVC = Ahorro Voluntario Contractual
B17: TOTALES | E17: =SUM(E7:E16) -> 24809754 | F17: =SUM(F7:F16) -> 913348.33 | G17: =SUM(G7:G16) -> 300000 | H17: =SUM(H7:H16) -> 1814083.4 | I17: =SUM(I7:I16) -> 1472362 | J17: =SUM(J7:J16) -> 29309548 | K17: =SUM(K7:K16) -> 1135848 | L17: =SUM(L7:L16) -> 1135848 | ... R17: =SUM(R7:R16) -> 25561033 | T17: Total Rentas Exentas | V17: =U15+U16 -> 0
T18: SUBTOTAL 2 = (SUBTOTAL 1 - TOTAL DEDUCCIONES - TOTAL RENTAS EXENTAS) | V18: =V8-V13-V17 -> 13633032
C19: APROPIACIONES | F19: SENA | G19: ICBF | H19: CAJA DE COMP | J19: SALUD | K19: PENSION | L19: ARL | N19: VACACIONES | O19: CESANTIAS | Q19: INTERESES | R19: PRIMA | T19: (-) 25% del subtotal 2, sin que anualmente exceda de 790 UVT | V19: =V18*0.25 -> 3408258
F20: 0.02 | G20: 0.03 | H20: 0.04 | J20: 0.085 | K20: 0.12 | L20: 0.01044 | N20: 0.0417 | O20: 0.0833 | Q20: 0.01 | R20: 0.0833 | T20: SUBTOTAL 3 = (SUBTOTAL 2 - 25%) | V20: =V18-V19 -> 10224774
F21: =(J7-I7-F7)*F20 -> 358000 | G21: =(J7-I7-F7)*G20 -> 537000 | H21: =(J17-I17-F17)*H20 -> 1076953.5 | J21: =(J7-I7-F7)*J20 -> 1521500 | K21: =(J17-F17)*K20 -> 3407543.9 | L21: =(J17-I17-F17)*L20 -> 281084.86 | N21: =(J17-I17-F17)*N20 -> 1122724 | O21: =$J$17*O20 -> 2441485.3 | Q21: =$J$17*Q20 -> 293095.48 | R21: =$J$17*R20 -> 2441485.3
T22: VALOR DE LA UVT AÑO 2026 | U22: 52374
T23: 40% DEL SUBTOTAL 1 | U23: =V8*0.4 -> 6515600 | V23: =V8*0.4 -> 6515600
T24: TOTAL DEDUCCIONES + TOTAL RENTAS EXENTAS + 25% EXENTO | U24: =V13+V17+V19 -> 6064226 | V24: =V13+V17+V19 -> 6064226
T25: INGRESO BASE DE RETENCIÓN EN PESOS | V25: =V20 -> 10224774
T26: INGRESO BASE DE RETENCIÓN ENUVT | V26: =ROUND(V25/U22,0) -> 195 | W26: =V25/U22 -> 195.22614
T27: VALOR DE LA RETENCIÓN | U27: =ROUND(V27*U22,-3) -> 1184000 | V27: =(V26-150)*0.28+10 -> 22.6
L28: CALCULO DEL PAGO DE INCAPACIDADES CORRESPONDIENTES A EMLPLEADOR, EPS Y ARL | T28: COMO DETERMINAR EL INGRESO LABORAL GRAVADO EXPRESADO EN PESOS
B29: NOMBRES DE LOS TRABAJADORES | E29: NUMERO DE HORAS EXTRAS Y RECARGOS | L29: ENFERMEDAD GENERAL | N29: RIESGOS LABORALES | P29: LICENCIA MATERNIDAD | R29: TOTALES | T29: CASO 1: CUANDO EL 40% DEL SUBTORAL 1 ES MAYOR QUE (TOTAL DEDUCCIONES + TOTAL RENTAS EXENTAS + 25% EXENTO)
E30: D Y F | F30: RN | G30: HEDO | H30: HENO | I30: HEDF | J30: HENF | L30: EMPLEADOR | M30: EPS | N30: EMPLEADOR | O30: ARL | Q30: EPS | T30: EN ESTE CASO, EL INGRESO LABORAL GRAVADO ES IGUAL AL SUBTOTAL 3 | U30: =+IF(V23>=(V13+V17+V19),V20,0) -> 10224774
B31: =B7 -> BERNARDO ROJAS | P31: PAGAEPS | R31: =SUM(L31:Q31) -> 0
B32: =B8 -> LEONARDO ROSAS | E32: =3*8 -> 24 | I32: =3*2 -> 6 | R32: =SUM(L32:Q32) -> 0 | T32: CASO 2: CUANDO EL 40% DEL SUBTORAL 1 ES MENOR QUE (TOTAL DEDUCCIONES + TOTAL RENTAS EXENTAS + 25% EXENTO)
B33: =B9 -> GERARDO VALVERDE | L33: =$C$1*2/30 -> 116727 | M33: =$C$1*5/30 -> 291817.5 | R33: =SUM(L33:Q33) -> 408544.5 | T33: EN ESTE CASO, EL INGRESO LABORAL GRAVADO SE OBTIENEN MEDIANTE LOS SIGUIENTES CÁLCULOS:
B34: =B10 -> EDUARDO BLANCO | E34: =2*8 -> 16 | N34: =C10*1/30 -> 58363.5 | O34: =C10*4/30 -> 233454 | R34: =SUM(L34:Q34) -> 291817.5 | T34: TOTAL DEDUCCIONES + TOTAL RENTAS EXENTAS + 25% EXENTO | U34: =V24 -> 6064226
B35: =B11 -> GILDARDO AMARILLA | F35: =7*20 -> 140 | H35: =2*20 -> 40 | R35: =SUM(L35:Q35) -> 0 | T35: (-) 40% DEL SUBTOTAL 1 | U35: =V23 -> 6515600
B36: =B12 -> JASMIN PEÑALOZA | Q36: =C12*12/30 -> 772000 | R36: =SUM(L36:Q36) -> 772000 | T36: (+) SUBTOTAL 3 | U36: =V20 -> 10224774
B37: FACTORES PARA CALCULAR HORA EXTRAS Y RECARGO | E37: 1.9 | F37: 0.35 | G37: 1.25 | H37: 1.75 | I37: 2.15 | J37: 2.65 | K37: TOTALES | L37: =SUM(L31:L36) -> 116727 | M37: =SUM(M31:M36) -> 291817.5 | N37: =SUM(N31:N36) -> 58363.5 | O37: =SUM(O31:O36) -> 233454 | Q37: =SUM(Q31:Q36) -> 772000 | R37: =SUM(R31:R36) -> 1472362 | T37: (=) (INGRESO LABORAL GRAVADO EXPRESADO EN PESOS | U37: =U34-U35+U36 -> 9773400
L38: TOTAL EMPLEADOR = | R38: =L37+N37 -> 175090.5 | T38: CASO 2: OTRA FORMA DE CALCULARLO
L39: PAGO POR CUENTA DE TERCEROS 237.333+500.000+520.000 | R39: =M37+O37+Q37 -> 1297271.5 | T39: SUBOTAL 1 | U39: =V8 -> 16289000
T40: (-) 40% DEL SUBTOTAL 1 | U40: =V23 -> 6515600
...

Sheet TABLA RETENCIÓN
C2: UVT | D2: 52374
B3: Rangos en UVT | D3: Tarifa marginal | E3: Instrucción para calcular la retención ("impuesto") en $
B4: >0 | C4: 95 | D4: 0 | E4: 0
B5: >95 | C5: 150 | D5: 0.19 | E5: (Ingreso laboral gravado expresado en UVT menos 95 UVT) × 19 %
B6: >150 | C6: 360 | D6: 0.28 | E6: (Ingreso laboral gravado expresado en UVT menos 150 UVT) × 28 % más 10 UVT
B7: >360 | C7: 640 | D7: 0.33 | E7: (Ingreso laboral gravado expresado en UVT menos 360 UVT) × 33 % más 69 UVT
B8: >640 | C8: 945 | D8: 0.35 | E8: (Ingreso laboral gravado expresado en UVT menos 640 UVT) × 35 % más 162 UVT
B9: >945 | C9: 2300 | D9: 0.37 | E9: (Ingreso laboral gravado expresado en UVT menos 945 UVT) × 37 % más 268 UVT
B10: >2300 | C10: En adelante | D10: 0.39 | E10: (Ingreso laboral gravado expresado en UVT menos 2300 UVT) × 39 % más 770 UVT

Sheet CONTABILIZACION DE LA NOMIN (2)
A2: CONTABILIZACION DE LOS VALORES DEVENGADOS, LAS DEDUCCIONES Y EL NETO A PAGAR LA NOMINA MEDIANTE CUENTAS T | H2: CONTABILIZACION DE LOS VALORES DEVENGADOS, LAS DEDUCCIONES Y EL NETO A PAGAR DE LA NOMINA MEDIANTE COMPROBANTE DE CONTABILIDAD
B4: 510506 SUELDOS | E4: 510515 HORAS EXTRAS Y RECARGOS | H4: CODIGO | I4: CUENTAS | J4: PARCIALES | K4: DEBITOS | L4: CREDITOS
B5: ='FORMATO NOMINA'!E17 -> 24809754 | E5: ='FORMATO NOMINA'!H17 -> 1814083.4 | H5: 5105 | I5: GASTOS DE PERSONAL | K5: =SUM(J6:J10) -> 28012276
H6: 510506 | I6: Sueldos | J6: =B5 -> 24809754
B7: 510518 BONIFICASIONES | E7: 510524 INCAPACIDADES | H7: 510515 | I7: Horas Extras y Recargos | J7: =E5 -> 1814083.4
B8: ='FORMATO NOMINA'!G17 -> 300000 | E8: ='FORMATO NOMINA'!R38 -> 175090.5 | H8: 510548 | I8: Bonificasiones | J8: =B8 -> 300000
H9: 510524 | I9: Incapacidades | J9: =E8 -> 175090.5
B10: 138025 PAGOS POR CUENTA DE TERCEROS | E10: 510527 AUXILIO DE TRANSPORTE | H10: 510527 | I10: Auxilio de Transporte | J10: =E11 -> 913348.33
B11: ='FORMATO NOMINA'!R39 -> 1297271.5 | E11: ='FORMATO NOMINA'!F17 -> 913348.33 | H11: 1380 | I11: DEUDORES VARIOS | K11: =J12 -> 1297271.5 | O11: 14529704
H12: 138025 | I12: Pagos por Cuenta de Terceros | J12: =B11 -> 1297271.5 | O12: 320000
B13: 237040 A COOPERATIVAS | E13: 236505 SALARIOS Y PAGOS LABORALES | H13: 2365 | I13: RETENCION EN LA FUENTE | L13: =J14 -> 1184000
C14: ='FORMATO NOMINA'!P17 -> 100000 | F14: ='FORMATO NOMINA'!N17 -> 1184000 | H14: 236505 | I14: Salarios y Pagos Laborales | J14: =F14 -> 1184000
H15: 2370 | I15: RETENCIONES Y APORTES DE NOMINA | L15: =J17+J16+J18 -> 1249667
B16: 237005 APORTES A EPS | E16: 237025 EMBARGOS JUDICIALES | H16: 237005 | I16: Aportes a EPS | J16: =C17 -> 1135848
C17: ='FORMATO NOMINA'!K17 -> 1135848 | F17: ='FORMATO NOMINA'!O17 -> 13819 | H17: 237025 | I17: Embargos | J17: =F17 -> 13819
H18: 237040 | I18: Cooperativas | J18: =C14 -> 100000
B19: 238030 FONDOS DE C. Y/O PENSIONES | E19: 111005 MONEDA NACIONAL | H19: 2380 | I19: ACREEDORES VARIOS | L19: =J20 -> 1314848
C20: ='FORMATO NOMINA'!L17+'FORMATO NOMINA'!M17 -> 1314848 | F20: ='FORMATO NOMINA'!R17 -> 25561033 | H20: 238030 | I20: Fondos de Cesantias y/o Pensiones | J20: =C20 -> 1314848 | O20: =SUM(O11:O19) -> 14849704
H21: 1110 | I21: BANCOS | L21: =J22 -> 25561033
H22: 111005 | I22: Moneda Nacional | J22: =F20 -> 25561033
B23: EXPLICACION A LOS REGISTROS CONTABLES | H23: TOTALES | K23: =SUM(K5:K22) -> 29309548 | L23: =SUM(L5:L22) -> 29309548
B24: VALORES DEVENGADOS | M24: =K23-L23 -> 0
B25: Los pagos por salarios, bonificaciones, horas extras, auxilio de transporte,
B26: constituye para la empresa gasto de personal, que como sabemos son cuentas
B27: de naturaleza debito, que según el caso se deben clasificar como gastos de
B28: administraciòn (grupo 51) o gasto de ventas (grupo 52)
B29: DEDUCCIONES
B30: Los valores descontados por salud, pensiòn, retenciòn en la fuente, embargos, | H30: La diferencia entre lo devengado y las deducciones, es lo que se le debe entregar al
B31: constituye para la empresa pasivos, ya que son valore que debe pagar, normalmente, | H31: trabajador. Sì el pago es inmediato con dinero del banco, se disminuye la cuenta 1110
B32: al mes siguiente. En cuanto al anticipo, corresponde al pago anticipado que de su | H32: acreditandola. Sì por el contrario se les queda debiendo, se acredita la cuenta de pasivo
B33: salario hace la empresa a sus trabajadores, por los cuales debita la cuenta de activo | H33: 2505 Salarios por Pagar
B34: 1330 al momento del anticipo y acredita, cuando le hace el descuento a traves de la
B35: nòmina.
A38: CONTABILIZACION DE LAS APROPIACIONES DE LA NOMINA MEDIANTE LA UTILIZACION DE LAS CUENTAS T | H38: CONTABILIZACION DE LOS VALORES DEVENGADOS, LAS DEDUCCIONES Y EL NETO A PAGAR DE LA NOMINA MEDIANTE COMPROBANTE DE CONTABILIDAD
B40: 510530 CESANTIAS | E40: 510533 INTERESES SOBRE CESANTIAS | H40: CODIGO | I40: CUENTAS | J40: PARCIALES | K40: DEBITOS | L40: CREDITOS
B41: ='FORMATO NOMINA'!O21 -> 2441485.3 | E41: ='FORMATO NOMINA'!Q21 -> 293095.48 | H41: 5105 | I41: GASTOS DE PERSONAL | K41: =SUM(J42:J51) -> 13480872
H42: 510530 | I42: Cesantias | J42: =B41 -> 2441485.3
B43: 510536 PRIMA DE SERVICIOS | E43: 510539 VACACIONES | H43: 510533 | I43: Intereses Sobre Cesantias | J43: =E41 -> 293095.48
B44: ='FORMATO NOMINA'!R21 -> 2441485.3 | E44: ='FORMATO NOMINA'!N21 -> 1122724 | H44: 510536 | I44: Prima De Servicios | J44: =B44 -> 2441485.3
H45: 510539 | I45: Vacaciones | J45: =E44 -> 1122724
...
