Workbook

Sheet Resumen mensual
A1: Cuenta 13659501 OTROS — Carlos Andrade: movimiento y saldo por mes
A3: Mes | B3: Débitos (cobros) | C3: Créditos (descuentos) | D3: Neto del mes | E3: Saldo a fin de mes | F3: Estado | G3: Cambio vs mes anterior
A4: 44866 | B4: =SUMIFS('carlos andrade'!$J$7:$J$229,'carlos andrade'!$A$7:$A$229,">="&$A4,'carlos andrade'!$A$7:$A$229,"<"&EDATE($A4,1)) -> 277936 | C4: =SUMIFS('carlos andrade'!$K$7:$K$229,'carlos andrade'!$A$7:$A$229,">="&$A4,'carlos andrade'!$A$7:$A$229,"<"&EDATE($A4,1)) -> 138968 | D4: =B4-C4 -> 138968 | E4: =D4 -> 138968 | F4: =IF(E4=0,"Cuadrado en 0","Diferencia") -> Diferencia | G4: =E4 -> 138968
A5: 44896 | B5: =SUMIFS('carlos andrade'!$J$7:$J$229,'carlos andrade'!$A$7:$A$229,">="&$A5,'carlos andrade'!$A$7:$A$229,"<"&EDATE($A5,1)) -> 138968 | C5: =SUMIFS('carlos andrade'!$K$7:$K$229,'carlos andrade'!$A$7:$A$229,">="&$A5,'carlos andrade'!$A$7:$A$229,"<"&EDATE($A5,1)) -> 277936 | D5: =B5-C5 -> -138968 | E5: =E4+D5 -> 0 | F5: =IF(E5=0,"Cuadrado en 0","Diferencia") -> Cuadrado en 0 | G5: =E5-E4 -> -138968
A6: 44927 | B6: =SUMIFS('carlos andrade'!$J$7:$J$229,'carlos andrade'!$A$7:$A$229,">="&$A6,'carlos andrade'!$A$7:$A$229,"<"&EDATE($A6,1)) -> 125504 | C6: =SUMIFS('carlos andrade'!$K$7:$K$229,'carlos andrade'!$A$7:$A$229,">="&$A6,'carlos andrade'!$A$7:$A$229,"<"&EDATE($A6,1)) -> 138968 | D6: =B6-C6 -> -13464 | E6: =E5+D6 -> -13464 | F6: =IF(E6=0,"Cuadrado en 0","Diferencia") -> Diferencia | G6: =E6-E5 -> -13464
A7: 44958 | B7: =SUMIFS('carlos andrade'!$J$7:$J$229,'carlos andrade'!$A$7:$A$229,">="&$A7,'carlos andrade'!$A$7:$A$229,"<"&EDATE($A7,1)) -> 155798 | C7: =SUMIFS('carlos andrade'!$K$7:$K$229,'carlos andrade'!$A$7:$A$229,">="&$A7,'carlos andrade'!$A$7:$A$229,"<"&EDATE($A7,1)) -> 140651 | D7: =B7-C7 -> 15147 | E7: =E6+D7 -> 1683 | F7: =IF(E7=0,"Cuadrado en 0","Diferencia") -> Diferencia | G7: =E7-E6 -> 15147
A8: 44986 | B8: =SUMIFS('carlos andrade'!$J$7:$J$229,'carlos andrade'!$A$7:$A$229,">="&$A8,'carlos andrade'!$A$7:$A$229,"<"&EDATE($A8,1)) -> 140651 | C8: =SUMIFS('carlos andrade'!$K$7:$K$229,'carlos andrade'!$A$7:$A$229,">="&$A8,'carlos andrade'!$A$7:$A$229,"<"&EDATE($A8,1)) -> 140651 | D8: =B8-C8 -> 0 | E8: =E7+D8 -> 1683 | F8: =IF(E8=0,"Cuadrado en 0","Diferencia") -> Diferencia | G8: =E8-E7 -> 0
A9: 45017 | B9: =SUMIFS('carlos andrade'!$J$7:$J$229,'carlos andrade'!$A$7:$A$229,">="&$A9,'carlos andrade'!$A$7:$A$229,"<"&EDATE($A9,1)) -> 140651 | C9: =SUMIFS('carlos andrade'!$K$7:$K$229,'carlos andrade'!$A$7:$A$229,">="&$A9,'carlos andrade'!$A$7:$A$229,"<"&EDATE($A9,1)) -> 140651 | D9: =B9-C9 -> 0 | E9: =E8+D9 -> 1683 | F9: =IF(E9=0,"Cuadrado en 0","Diferencia") -> Diferencia | G9: =E9-E8 -> 0
A10: 45047 | B10: =SUMIFS('carlos andrade'!$J$7:$J$229,'carlos andrade'!$A$7:$A$229,">="&$A10,'carlos andrade'!$A$7:$A$229,"<"&EDATE($A10,1)) -> 140651 | C10: =SUMIFS('carlos andrade'!$K$7:$K$229,'carlos andrade'!$A$7:$A$229,">="&$A10,'carlos andrade'!$A$7:$A$229,"<"&EDATE($A10,1)) -> 140651 | D10: =B10-C10 -> 0 | E10: =E9+D10 -> 1683 | F10: =IF(E10=0,"Cuadrado en 0","Diferencia") -> Diferencia | G10: =E10-E9 -> 0
A11: 45078 | B11: =SUMIFS('carlos andrade'!$J$7:$J$229,'carlos andrade'!$A$7:$A$229,">="&$A11,'carlos andrade'!$A$7:$A$229,"<"&EDATE($A11,1)) -> 140651 | C11: =SUMIFS('carlos andrade'!$K$7:$K$229,'carlos andrade'!$A$7:$A$229,">="&$A11,'carlos andrade'!$A$7:$A$229,"<"&EDATE($A11,1)) -> 140651 | D11: =B11-C11 -> 0 | E11: =E10+D11 -> 1683 | F11: =IF(E11=0,"Cuadrado en 0","Diferencia") -> Diferencia | G11: =E11-E10 -> 0
A12: 45108 | B12: =SUMIFS('carlos andrade'!$J$7:$J$229,'carlos andrade'!$A$7:$A$229,">="&$A12,'carlos andrade'!$A$7:$A$229,"<"&EDATE($A12,1)) -> 140651 | C12: =SUMIFS('carlos andrade'!$K$7:$K$229,'carlos andrade'!$A$7:$A$229,">="&$A12,'carlos andrade'!$A$7:$A$229,"<"&EDATE($A12,1)) -> 140651 | D12: =B12-C12 -> 0 | E12: =E11+D12 -> 1683 | F12: =IF(E12=0,"Cuadrado en 0","Diferencia") -> Diferencia | G12: =E12-E11 -> 0
A13: 45139 | B13: =SUMIFS('carlos andrade'!$J$7:$J$229,'carlos andrade'!$A$7:$A$229,">="&$A13,'carlos andrade'!$A$7:$A$229,"<"&EDATE($A13,1)) -> 140651 | C13: =SUMIFS('carlos andrade'!$K$7:$K$229,'carlos andrade'!$A$7:$A$229,">="&$A13,'carlos andrade'!$A$7:$A$229,"<"&EDATE($A13,1)) -> 142334 | D13: =B13-C13 -> -1683 | E13: =E12+D13 -> 0 | F13: =IF(E13=0,"Cuadrado en 0","Diferencia") -> Cuadrado en 0 | G13: =E13-E12 -> -1683
A14: 45170 | B14: =SUMIFS('carlos andrade'!$J$7:$J$229,'carlos andrade'!$A$7:$A$229,">="&$A14,'carlos andrade'!$A$7:$A$229,"<"&EDATE($A14,1)) -> 140651 | C14: =SUMIFS('carlos andrade'!$K$7:$K$229,'carlos andrade'!$A$7:$A$229,">="&$A14,'carlos andrade'!$A$7:$A$229,"<"&EDATE($A14,1)) -> 140651 | D14: =B14-C14 -> 0 | E14: =E13+D14 -> 0 | F14: =IF(E14=0,"Cuadrado en 0","Diferencia") -> Cuadrado en 0 | G14: =E14-E13 -> 0
A15: 45200 | B15: =SUMIFS('carlos andrade'!$J$7:$J$229,'carlos andrade'!$A$7:$A$229,">="&$A15,'carlos andrade'!$A$7:$A$229,"<"&EDATE($A15,1)) -> 165505 | C15: =SUMIFS('carlos andrade'!$K$7:$K$229,'carlos andrade'!$A$7:$A$229,">="&$A15,'carlos andrade'!$A$7:$A$229,"<"&EDATE($A15,1)) -> 165505 | D15: =B15-C15 -> 0 | E15: =E14+D15 -> 0 | F15: =IF(E15=0,"Cuadrado en 0","Diferencia") -> Cuadrado en 0 | G15: =E15-E14 -> 0
A16: 45231 | B16: =SUMIFS('carlos andrade'!$J$7:$J$229,'carlos andrade'!$A$7:$A$229,">="&$A16,'carlos andrade'!$A$7:$A$229,"<"&EDATE($A16,1)) -> 171536 | C16: =SUMIFS('carlos andrade'!$K$7:$K$229,'carlos andrade'!$A$7:$A$229,">="&$A16,'carlos andrade'!$A$7:$A$229,"<"&EDATE($A16,1)) -> 165505 | D16: =B16-C16 -> 6031 | E16: =E15+D16 -> 6031 | F16: =IF(E16=0,"Cuadrado en 0","Diferencia") -> Diferencia | G16: =E16-E15 -> 6031
... A50: 46266 | B50: =SUMIFS('carlos andrade'!$J$7:$J$229,'carlos andrade'!$A$7:$A$229,">="&$A50,'carlos andrade'!$A$7:$A$229,"<"&EDATE($A50,1)) -> 190990 | C50: =SUMIFS('carlos andrade'!$K$7:$K$229,'carlos andrade'!$A$7:$A$229,">="&$A50,'carlos andrade'!$A$7:$A$229,"<"&EDATE($A50,1)) -> 282974 | D50: =B50-C50 -> -91984 | E50: =E49+D50 -> 94827 | F50: =IF(E50=0,"Cuadrado en 0","Diferencia") -> Diferencia | G50: =E50-E49 -> -91984
A51: Total | B51: =SUM(B4:B50) -> 9723034 | C51: =SUM(C4:C50) -> 9628207 | D51: =SUM(D4:D50) -> 94827 | E51: =E50 -> 94827 | F51: =IF(ROUND(E51-'carlos andrade'!L229,0)=0,"✔ cuadra con el auxiliar","revisar") -> ✔ cuadra con el auxiliar

Sheet Por qué 94.827
A1: ¿De dónde salen los $94.827 al 30/09/2026?
A3: Concepto | B3: Valor | C3: Qué pasó
A4: Saldo a 31/07/2026 (antes del ajuste) | B4: ='Resumen mensual'!E48 -> -495180 | C4: Descuentos de póliza de vehículo/exequial superiores a lo amortizado/facturado desde sep-2025
A5: + NT-12625 del 31/08/26 "Corrección tercero NTE 12088" | B5: =SUM('carlos andrade'!J216:J221) -> 619402 | C5: Débito: amortizaciones (35.700, 131.733, 142.268, cada una x2) pasadas a este tercero
A6: + FSC-11290 del 27/08/26 póliza moto (62.590) cobrada y no descontada en agosto | B6: ='carlos andrade'!J215 -> 62590 | C6: En agosto la quincena solo descontó 117.897 (carro + exequial), sin la moto. En septiembre se descontó la de septiembre
A7: ± Otros movimientos de ago-sep 2026 (septiembre cobro 190.990 vs descuento 190.991, etc.) | B7: =B9-B4-B5-B6-B8 -> -2 | C7: Diferencia de redondeo
A8: − NF-355 del 30/09/26 descuento póliza de salud (feb-mar-abr) | B8: =-SUM('carlos andrade'!K227:K229) -> -91983 | C8: Las facturas de salud (FSC-9538 y 9539, 91.984) ya habían sido anuladas con las NC de abril (NT-12434 y 12435). Este descuento queda sin cobro que lo respalde
A9: Saldo al 30/09/2026 (resultado) | B9: ='carlos andrade'!L229 -> 94827
A11: Reparto del resultado (sin el descuento de salud): 186.810 corresponden a vehículo/exequial y −91.983 al descuento de salud sin cobro.

Sheet carlos andrade
I1: Saldo inicial a | L1: Saldo final a
A2: Fecha | B2: Documento | C2: C.O. | D2: U.N. | I2: 1/01/2020 | J2: Débitos | K2: Créditos | L2: 30/09/2026
A5: 13659501 | B5: OTROS | I5: 0 | J5: 9723034 | K5: 9628207 | L5: 94827
A6: 94504468 ANDRADE IMBACHI CARLOS | I6: 0 | J6: 9723034 | K6: 9628207 | L6: 94827
A7: 44875 | B7: 001-NQ-00000499 | C7: 001 | D7: 99 | E7: - 1a QUINCENA NOVIEMBRE DE 2022 | J7: 0 | K7: 138968 | L7: -138968
A8: 44887 | B8: 001-NB-00001817 | C8: 001 | D8: 99 | E8: - REG,PAGO FACTURA COMPRA DE SEGUROS OBLIGATORIO CORPORATIVO NSI MES DE OCTUBRE 2022 | J8: 138968 | K8: 0 | L8: 0
A9: 44890 | B9: 001-FSC-00003312 | C9: 001 | D9: 99 | E9: - REG,FACTURA COMPRA DE SEGUROS OBLIGATORIO CORPORATIVO N S I MES DE NOV 2022 | J9: 49809 | K9: 0 | L9: 49809
A10: 44890 | B10: 001-FSC-00003312 | C10: 001 | D10: 99 | E10: - REG,FACTURA COMPRA DE SEGUROS OBLIGATORIO CORPORATIVO N S I MES DE NOV 2022 | J10: 89159 | K10: 0 | L10: 138968
A11: 44908 | B11: 001-NQ-00000503 | C11: 001 | D11: 99 | E11: - 1a QUINCENA DICIEMBRE DE 2022 | J11: 0 | K11: 138968 | L11: 0
A12: 44914 | B12: 001-LV-00000062 | C12: 001 | D12: 99 | E12: - VACACIONES COLECTIVAS 2022 | J12: 0 | K12: 138968 | L12: -138968
A13: 44915 | B13: 001-FSC-00003369 | C13: 001 | D13: 99 | E13: - REG,FACTURA COMPRA DE SEGUROS OBLIGATORIO CORPORATIVO N S I MES DE DIC 2022 | J13: 49809 | K13: 0 | L13: -89159
A14: 44915 | B14: 001-FSC-00003369 | C14: 001 | D14: 99 | E14: - REG,FACTURA COMPRA DE SEGUROS OBLIGATORIO CORPORATIVO N S I MES DE DIC 2022 | J14: 89159 | K14: 0 | L14: 0
A15: 44939 | B15: 001-NQ-00000505 | C15: 001 | D15: 99 | E15: - 1a QUINCENA ENERO DE 2023 | J15: 0 | K15: 138968 | L15: -138968
A16: 44957 | B16: 001-FSC-00003456 | C16: 001 | D16: 99 | E16: - FACTURA COMPRA SEGUROS VEHICULOS CORPORATIVO N S I MES DE ENERO 2023 | J16: 36345 | K16: 0 | L16: -102623
A17: 44957 | B17: 001-FSC-00003456 | C17: 001 | D17: 99 | E17: - FACTURA COMPRA SEGUROS VEHICULOS CORPORATIVO N S I MES DE ENERO 2023 | J17: 89159 | K17: 0 | L17: -13464
A18: 44964 | B18: 001-NQ-00000509 | C18: 001 | D18: 99 | E18: - 1a Quincena Febrero 2023 | J18: 15147 | K18: 0 | L18: 1683
... A53: 45315 | B53: 001-FSC-00004423 | C53: 001 | D53: 99 | E53: - SEGURO VEHICULAR CORPORATIVO ENERO 2024 | J53: 171536 | K53: 0 | L53: 171536
A54: 45315 | B54: 001-NT-00010999 | C54: 001 | D54: 99 | E54: - RECLASIF NT 10979 ENERO 2024 | J54: 0 | K54: 171536 | L54: 0 | M54: OK
A55: 45335 | B55: 001-NQ-00000548 | C55: 001 | D55: 99 | E55: - 1a QUincena Febrero de 2024 | J55: 0 | K55: 171536 | L55: -171536
A56: 45342 | B56: 001-FSC-00004495 | C56: 001 | D56: 99 | E56: - DESC SEGURO VEHICULAR CORPORATIVO FEB 2024 | J56: 171536 | K56: 0 | L56: 0
A57: 45364 | B57: 001-NQ-00000552 | C57: 001 | D57: 99 | E57: - 1a Quincena Marzo de 2024 | J57: 0 | K57: 181036 | L57: -181036
A58: 45372 | B58: 001-NQ-00000554 | C58: 001 | D58: 99 | E58: - 2a Quincena Mar 2024 y vacacio | J58: 0 | K58: 9500 | L58: -190536
A59: 45382 | B59: 001-FSC-00004642 | C59: 001 | D59: 99 | E59: - DESC SEGURO VEHICULAR MARZO ABRIL 2024 | J59: 167094 | K59: 0 | L59: -23442
A60: 45382 | B60: 001-FSC-00004642 | C60: 001 | D60: 99 | E60: - DESC SEGURO VEHICULAR MARZO ABRIL 2024 | J60: 171536 | K60: 0 | L60: 148094
A61: 45382 | B61: 001-NT-00011157 | C61: 001 | D61: 99 | E61: - RECLASIFICACION DE NIT COBRO SEG VEHICULAR MARZ ABRIL 2024 | J61: 0 | K61: 167094 | L61: -19000
A62: 45394 | B62: 001-NQ-00000556 | C62: 001 | D62: 99 | E62: - 1a Quincena Abril de 2024 | J62: 0 | K62: 181036 | L62: -200036
A63: 45405 | B63: 001-FSC-00004691 | C63: 001 | D63: 99 | E63: - POLIZA DE SEGURO EXEQUIAL MARZO 2024 | J63: 19000 | K63: 0 | L63: -181036
A64: 45407 | B64: 001-NQ-00000558 | C64: 001 | D64: 99 | E64: - 2a Quincena Abril de 2024 | J64: 0 | K64: 9500 | L64: -190536
A65: 45412 | B65: 001-FSC-00004704 | C65: 001 | D65: 99 | E65: - DESC SEGURO VEHICLUAR ABRIL MAYO 2024 | J65: 171536 | K65: 0 | L65: -19000
A66: 45422 | B66: 001-FSC-00004815 | C66: 001 | D66: 99 | E66: - SEGURO VEHICULAR CORPORATIVO MAYO JUNIO 2024 | J66: 171536 | K66: 0 | L66: 152536
... A98: 45657 | B98: 001-NT-00011672 | C98: 001 | D98: 99 | E98: - AMORTIZACION DIFERIDOS DICIEMBRE 2024 | J98: 131733 | K98: 0 | L98: -363366
A99: 45657 | B99: 001-NT-00011690 | C99: 001 | D99: 99 | E99: - RECL. PROVSIONAL CTA SALDO INVERSO POR DES. VACACIONES | J99: 363366 | K99: 0 | L99: 0 | M99: ok
A100: 45671 | B100: 001-FSC-00006605 | C100: 001 | D100: 99 | E100: - FACT. VT-8267577 POLIZA SEGURO EXEQUIAL DIC/24 | J100: 19000 | K100: 0 | L100: 19000
A101: 45684 | B101: 001-NQ-00000587 | C101: 001 | D101: 99 | E101: - 2a Quincena Enero de 2024 | J101: 0 | K101: 9500 | L101: 9500
A102: 45688 | B102: 001-NT-00011731 | C102: 001 | D102: 99 | E102: - REV. ANTICIPOS DE DESCUENTOS POR VACACIONES | J102: 0 | K102: 363366 | L102: -353866
A103: 45688 | B103: 001-NT-00011739 | C103: 001 | D103: 99 | E103: - AMORTIZACION DIFERIDOS ENERO 2025 | J103: 35700 | K103: 0 | L103: -318166
A104: 45688 | B104: 001-NT-00011739 | C104: 001 | D104: 99 | E104: - AMORTIZACION DIFERIDOS ENERO 2025 | J104: 131733 | K104: 0 | L104: -186433
A105: 45699 | B105: 001-FSC-00006824 | C105: 001 | D105: 99 | E105: - FACT. VT-9117974 SEGURO EXEQUIAL EMPLEADOS ENE/25 | J105: 19000 | K105: 0 | L105: -167433
A106: 45701 | B106: 001-NQ-00000588 | C106: 001 | D106: 99 | E106: - 1a QUINCENA FEBRERO DE 2025 | J106: 0 | K106: 176933 | L106: -344366
A107: 45715 | B107: 001-NQ-00000589 | C107: 001 | D107: 99 | E107: - 2A QUINCENA FEB 2025 | J107: 0 | K107: 9500 | L107: -353866
...
